Workbook
Name IQ_CH: 110000
Name IQ_CQ: 5000
Name IQ_CY: 10000
Name IQ_DAILY: 500000
Name IQ_FH: 100000
Name IQ_FQ: 500
Name IQ_FY: 1000
Name IQ_LTM: 2000
Name IQ_MONTH: 15000
Name IQ_NTM: 6000
Name IQ_WEEK: 50000
Name IQ_YTD: 3000

Sheet Cover Page

Sheet TOC
B3: Table of Contents
B5: Particulars | D5: Exihibit No.
B7: Revenue Driver | D7: 1
B8: Income Statement | D8: =D7+1 -> 2
B9: Weighted Average Cost of Capital | D9: =D8+1 -> 3
B10: Discounted Cash Flow | D10: =D9+1 -> 4

Sheet Drivers
B2: ="Exihibit "&VLOOKUP(Drivers!B3,TOC!$B$7:$D$10,3,FALSE) -> Exihibit 1
B3: Revenue Driver
B5: Fiscal Year ending December | D5: 2019 | E5: =D5+1 -> 2020 | F5: =E5+1 -> 2021 | G5: =F5+1 -> 2022 | H5: =G5+1 -> 2023 | I5: =H5+1 -> 2024 | J5: =I5+1 -> 2025 | K5: =J5+1 -> 2026 | L5: =K5+1 -> 2027 | ... O5: =N5+1 -> 2030
B7: By Location
B8: UK | D8: 3681 | E8: 3751 | F8: 3935 | G8: 4324 | H8: 6102 | I8: 7039 | J8: 7876 | K8: =K26*K28 -> 7104.3376 | L8: =L26*L28 -> 8032.4518 | M8: =M26*M28 -> 9056.1019 | N8: =N26*N28 -> 10155.29 | O8: =O26*O28 -> 11009.871
B9: Europe | D9: 1156 | E9: 1235 | F9: 1502 | G9: 1824 | H9: 1533 | I9: 1733 | J9: 2221 | K9: =K45*K47 -> 2662.9153 | L9: =L45*L47 -> 2946.8943 | M9: =M45*M47 -> 3175.1644 | N9: =N45*N47 -> 3336.12 | O9: =O45*O47 -> 4034.5936
B10: US | D10: 8635 | E10: 9309 | F10: 9108 | G10: 10157 | H10: 10700 | I10: 12559 | J10: 13145 | K10: =K36*K35 -> 15462.582 | L10: =L36*L35 -> 15671.471 | M10: =M36*M35 -> 15723.622 | N10: =N36*N35 -> 15913.808 | O10: =O36*O35 -> 16121.175
B11: Saudi Arabia | D11: 2593 | E11: 2631 | F11: 2476 | G11: 2540 | H11: 2687 | I11: 2892 | J11: 2838 | K11: =K51*K53*1000 -> 3314.9277 | L11: =L51*L53*1000 -> 3388.7451 | M11: =M51*M53*1000 -> 3374.4959 | N11: =N51*N53*1000 -> 3496.2584 | O11: =O51*O53*1000 -> 3738.8449
B12: Other | D12: =D13+D14+D15+D16+D17 -> 2240 | E12: =E13+E14+E15+E16+E17 -> 2351 | F12: =F13+F14+F15+F16+F17 -> 2500 | G12: =G13+G14+G15+G16+G17 -> 2413 | H12: =H13+H14+H15+H16+H17 -> 2056 | I12: =I13+I14+I15+I16+I17 -> 2089 | J12: =J13+J14+J15+J16+J17 -> 2256 | K12: =AVERAGE(D12:J12) -> 2272.1429 | L12: =AVERAGE(E12:K12) -> 2276.7347 | M12: =AVERAGE(F12:L12) -> 2266.1254 | N12: =AVERAGE(G12:M12) -> 2232.7147 | O12: =AVERAGE(H12:N12) -> 2206.9597
B13: Canada | D13: 129 | E13: 114 | F13: 141 | G13: 125 | H13: 177 | I13: 189 | J13: 227
B14: Qatar | D14: 0 | E14: 913 | F14: 1014 | G14: 885 | H14: 450 | I14: 259 | J14: 252
B15: Australia | D15: 667 | E15: 664 | F15: 762 | G15: 853 | H15: 943 | I15: 1158 | J15: 1287
B16: Asia & Pacific | D16: 423 | E16: 332 | F16: 285 | G16: 283 | H16: 264 | I16: 354 | J16: 358
B17: Other | D17: 1021 | E17: 328 | F17: 298 | G17: 267 | H17: 222 | I17: 129 | J17: 132
B18: Revenue from Regions | D18: =SUM(D8:D12) -> 18305 | E18: =SUM(E8:E12) -> 19277 | F18: =SUM(F8:F12) -> 19521 | G18: =SUM(G8:G12) -> 21258 | H18: =SUM(H8:H12) -> 23078 | I18: =SUM(I8:I12) -> 26312 | J18: =SUM(J8:J12) -> 28336 | K18: =SUM(K8:K17) -> 30816.905 | L18: =SUM(L8:L17) -> 32316.297 | M18: =SUM(M8:M17) -> 33595.51 | N18: =SUM(N8:N17) -> 35134.191 | O18: =SUM(O8:O17) -> 37111.444
B19: Turnover: Joint Ventures | D19: 1804 | E19: 1585 | F19: 1789 | G19: 1998 | H19: 2206 | I19: 2023 | J19: 2326 | K19: =J19*(1+K20) -> 2440.3853 | L19: =K19*(1+L20) -> 2629.7732 | M19: =L19*(1+M20) -> 2811.4615 | N19: =M19*(1+N20) -> 2983.3344 | O19: =N19*(1+O20) -> 3144.3481
B20: % growth | E20: =E19/D19-1 -> -0.1213969 | F20: =F19/E19-1 -> 0.12870662 | G20: =G19/F19-1 -> 0.11682504 | H20: =H19/G19-1 -> 0.1041041 | I20: =I19/H19-1 -> -0.082955576 | J20: =J19/I19-1 -> 0.14977756 | K20: =AVERAGE(E20:J20) -> 0.04917681 | L20: =AVERAGE(F20:K20) -> 0.07760576 | M20: =AVERAGE(G20:L20) -> 0.06908895 | N20: =AVERAGE(H20:M20) -> 0.061132934 | O20: =AVERAGE(I20:N20) -> 0.053971073
B21: Total Revenue | D21: =SUM(D18:D19) -> 20109 | E21: =SUM(E18:E19) -> 20862 | F21: =SUM(F18:F19) -> 21310 | G21: =SUM(G18:G19) -> 23256 | H21: =SUM(H18:H19) -> 25284 | I21: =SUM(I18:I19) -> 28335 | J21: =SUM(J18:J19) -> 30662 | K21: =SUM(K18:K19) -> 33257.291 | ... O21: =SUM(O18:O19) -> 40255.792
B23: UK Revenue Driver
B24: UK GDP (in tn) | D24: 2.85 | E24: 2.7 | F24: 3.14 | G24: 3.11 | H24: 3.37 | I24: 3.64 | J24: 3.67 | K24: =J24*(1+K25) -> 3.72505 | L24: =K24*(1+L25) -> 3.7809257 | M24: =L24*(1+M25) -> 3.8376396 | N24: =M24*(1+N25) -> 3.8952042 | O24: =N24*(1+O25) -> 3.9536323
B25: % growth | K25: 0.015 | L25: 0.015 | M25: 0.015 | N25: 0.015 | O25: 0.015
B26: UK Defense Expenditure (in mn) | D26: 38100 | E26: 39800 | F26: 42400 | G26: 45900 | H26: 52800 | I26: 53900 | J26: 60200 | K26: =K24*K27*1000*1000 -> 67507.65 | L26: =L24*L27*1000*1000 -> 75020.984 | M26: =M24*M27*1000*1000 -> 82744.53 | N26: =N24*N27*1000*1000 -> 90682.902 | O26: =O24*O27*1000*1000 -> 98840.807
B27: UK Defense Expenditure as % of GDP | D27: =(D26/1000)/(D24*1000) -> 0.013368421 | E27: =(E26/1000)/(E24*1000) -> 0.014740741 | F27: =(F26/1000)/(F24*1000) -> 0.013503185 | G27: =(G26/1000)/(G24*1000) -> 0.014758842 | H27: =(H26/1000)/(H24*1000) -> 0.015667656 | I27: =(I26/1000)/(I24*1000) -> 0.014807692 | J27: =(J26/1000)/(J24*1000) -> 0.01640327 | K27: =J27+($O$27-$J$27)/5 -> 0.018122616 | L27: =K27+($O$27-$J$27)/5 -> 0.019841962 | M27: =L27+($O$27-$J$27)/5 -> 0.021561308 | N27: =M27+($O$27-$J$27)/5 -> 0.023280654 | O27: 0.025
B28: UK Revenue as % of UK Defense Exp. | D28: =D8/D26 -> 0.096614173 | E28: =E8/E26 -> 0.094246231 | F28: =F8/F26 -> 0.092806604 | G28: =G8/G26 -> 0.094204793 | H28: =H8/H26 -> 0.11556818 | I28: =I8/I26 -> 0.13059369 | J28: =AVERAGE(D28:I28) -> 0.10400561 | K28: =AVERAGE(E28:J28) -> 0.10523752 | L28: =AVERAGE(F28:K28) -> 0.1070694 | M28: =AVERAGE(G28:L28) -> 0.10944653 | N28: =AVERAGE(H28:M28) -> 0.11198682 | O28: =AVERAGE(I28:N28) -> 0.11138993
B30: US Revenue Driver
B31: US GDP ($ tn) | D31: 21.54 | E31: 21.38 | F31: 23.73 | G31: 26.05 | H31: 27.81 | I31: 29.3 | J31: 29.8 | K31: =J31*(1+K32) -> 30.247 | L31: =K31*(1+L32) -> 30.700705 | M31: =L31*(1+M32) -> 31.161216 | N31: =M31*(1+N32) -> 31.628634 | O31: =N31*(1+O32) -> 32.103063
B32: % growth | E32: =E31/D31-1 -> -0.0074280409 | F32: =F31/E31-1 -> 0.10991581 | G32: =G31/F31-1 -> 0.09776654 | H32: =H31/G31-1 -> 0.06756238 | I32: =I31/H31-1 -> 0.05357785 | J32: =J31/I31-1 -> 0.017064846 | K32: 0.015 | L32: 0.015 | M32: 0.015 | N32: 0.015 | O32: 0.015
B33: US Defense Expenditure ($) | D33: 734340 | E33: 778400 | F33: 806230 | G33: 876940 | H33: 916010 | I33: 997300 | J33: 926800 | K33: =K31*K34*1000000 -> 1020685 | L33: =L31*L34*1000000 -> 1034473.8 | M33: =M31*M34*1000000 -> 1037916.3 | N33: =N31*N34*1000000 -> 1050470.4 | O33: =O31*O34*1000000 -> 1064158.8
B34: US Defense Exp. as % of US GDP | D34: =D33/(D31*1000000) -> 0.034091922 | E34: =E33/(E31*1000000) -> 0.036407858 | F34: =F33/(F31*1000000) -> 0.033975137 | G34: =G33/(G31*1000000) -> 0.033663724 | H34: =H33/(H31*1000000) -> 0.032938152 | I34: =I33/(I31*1000000) -> 0.034037543 | J34: =J33/(J31*1000000) -> 0.031100671 | K34: =AVERAGE(D34:J34) -> 0.033745001 | L34: =AVERAGE(E34:K34) -> 0.033695441 | M34: =AVERAGE(F34:L34) -> 0.033307953 | N34: =AVERAGE(G34:M34) -> 0.03321264 | O34: =AVERAGE(H34:N34) -> 0.0331482
B35: US Defense Expenditure (£) | D35: =D33/D57 -> 574106.79 | E35: =E33/E57 -> 602243.71 | F35: =F33/F57 -> 586562.39 | G35: =G33/G57 -> 711340.04 | H35: =H33/H57 -> 734747.73 | I35: =I33/I57 -> 780543.16 | J35: =J33/J57 -> 702014.85 | K35: =K33/K57 -> 773129.1 | ... O35: =O33/O57 -> 806058.75
B36: US Revenue as % of US Defense Exp. | D36: =D10/D35 -> 0.015040756 | E36: =E10/E35 -> 0.015457197 | F36: =F10/F35 -> 0.01552776 | G36: =G10/G35 -> 0.014278685 | H36: =H10/H35 -> 0.014562821 | I36: =I10/I35 -> 0.016090078 | J36: =AVERAGE(D36:I36) -> 0.015159549 | K36: =MAX(AVERAGE(E36:J36),2%) -> 0.02 | L36: =MAX(AVERAGE(F36:K36),2%) -> 0.02 | M36: =MAX(AVERAGE(G36:L36),2%) -> 0.02 | N36: =MAX(AVERAGE(H36:M36),2%) -> 0.02 | O36: =MAX(AVERAGE(I36:N36),2%) -> 0.02
B38: Europe Revenue Driver
B39: Europe GDP ($ trillions) | D39: 15.8 | E39: 15.5 | F39: 17.5 | G39: 17 | H39: 18.3 | I39: 19.4 | J39: 19.7 | K39: =J39*(1+K41) -> 20.094 | L39: =K39*(1+L41) -> 20.49588 | M39: =L39*(1+M41) -> 20.905798 | N39: =M39*(1+N41) -> 21.323914 | O39: =N39*(1+O41) -> 21.750392
B40: Europe GDP (€ trillions) | D40: =D39/D56 -> 14.134908 | E40: =E39/E56 -> 13.511158 | F40: =F39/F56 -> 14.833023 | G40: =G39/G56 -> 16.145883 | H40: =H39/H56 -> 16.917815 | I40: =I39/I56 -> 17.981277 | J40: =J39/J56 -> 17.416674 | K40: =K39/K56 -> 17.765008 | ... O40: =O39/O56 -> 19.229415
B41: % growth | E41: =E39/D39-1 -> -0.018987342 | F41: =F39/E39-1 -> 0.12903226 | G41: =G39/F39-1 -> -0.028571429 | H41: =H39/G39-1 -> 0.076470588 | I41: =I39/H39-1 -> 0.06010929 | J41: =J39/I39-1 -> 0.015463918 | K41: =MIN(AVERAGE(E41:J41),2%) -> 0.02 | L41: =MIN(AVERAGE(F41:K41),2%) -> 0.02 | M41: =MIN(AVERAGE(G41:L41),2%) -> 0.02 | N41: =MIN(AVERAGE(H41:M41),2%) -> 0.02 | O41: =MIN(AVERAGE(I41:N41),2%) -> 0.02
B42: Defense Spending as % of GDP | D42: 0.02 | E42: 0.02 | F42: 0.02 | G42: 0.02 | H42: 0.02 | I42: 0.02 | J42: 0.02 | K42: =J42+(($O$42-$J$42)/5) -> 0.022 | L42: =K42+(($O$42-$J$42)/5) -> 0.024 | M42: =L42+(($O$42-$J$42)/5) -> 0.026 | N42: =M42+(($O$42-$J$42)/5) -> 0.028 | O42: 0.03
B43: $ Defense Spending | D43: =((D39*D42)*1000)*1000 -> 316000 | E43: =((E39*E42)*1000)*1000 -> 310000 | F43: =((F39*F42)*1000)*1000 -> 350000 | G43: =((G39*G42)*1000)*1000 -> 340000 | H43: =((H39*H42)*1000)*1000 -> 366000 | I43: =((I39*I42)*1000)*1000 -> 388000 | J43: =((J39*J42)*1000)*1000 -> 394000 | K43: =((K39*K42)*1000)*1000 -> 442068 | ... O43: =((O39*O42)*1000)*1000 -> 652511.75
B45: Europe Defense Expenditure (€) | D45: 186000 | E45: 198000 | F45: 214000 | G45: 240000 | H45: 279000 | I45: 343200 | J45: 381000 | K45: =K46*K40*1000000 -> 424150.02 | L45: =L46*L40*1000000 -> 468873.63 | M45: =M46*M40*1000000 -> 515216.53 | N45: =N46*N40*1000000 -> 563225.6 | O45: =O46*O40*1000000 -> 673029.54
B46: € Defense Spending as % of GDP | D46: =D45/(D40*1000000) -> 0.013158911 | E46: =E45/(E40*1000000) -> 0.014654555 | F46: =F45/(F40*1000000) -> 0.014427269 | G46: =G45/(G40*1000000) -> 0.014864471 | H46: =H45/(H40*1000000) -> 0.016491492 | I46: =I45/(I40*1000000) -> 0.01908652 | J46: =J45/(J40*1000000) -> 0.021875589 | K46: =J46+(($O$42-$J$42)/5) -> 0.023875589 | L46: =K46+(($O$42-$J$42)/5) -> 0.025875589 | M46: =L46+(($O$42-$J$42)/5) -> 0.027875589 | N46: =M46+(($O$42-$J$42)/5) -> 0.029875589 | O46: 0.035
B47: Europe Revenue as % of Defense Exp. | D47: =D9/D45 -> 0.0062150538 | E47: =E9/E45 -> 0.0062373737 | F47: =F9/F45 -> 0.0070186916 | G47: =G9/G45 -> 0.0076 | H47: =H9/H45 -> 0.0054946237 | I47: =I9/I45 -> 0.0050495338 | J47: =AVERAGE(D47:I47) -> 0.0062692128 | K47: =AVERAGE(E47:J47) -> 0.0062782393 | L47: =AVERAGE(F47:K47) -> 0.0062850502 | M47: =AVERAGE(G47:L47) -> 0.0061627766 | N47: =AVERAGE(H47:M47) -> 0.0059232394 | O47: =AVERAGE(I47:N47) -> 0.0059946753
...

Sheet IS
B2: ="Exihibit "&VLOOKUP(B3,TOC!$B$7:$D$10,3,FALSE) -> Exihibit 2
B3: Income Statement
B5: Fiscal Year ending December | D5: 2019 | E5: =D5+1 -> 2020 | F5: =E5+1 -> 2021 | G5: =F5+1 -> 2022 | H5: =G5+1 -> 2023 | I5: =H5+1 -> 2024 | J5: =I5+1 -> 2025 | K5: =J5+1 -> 2026 | L5: =K5+1 -> 2027 | ... O5: =N5+1 -> 2030
B7: Revenue from Operation | D7: =Drivers!D18 -> 18305 | E7: =Drivers!E18 -> 19277 | F7: =Drivers!F18 -> 19521 | G7: =Drivers!G18 -> 21258 | H7: =Drivers!H18 -> 23078 | I7: =Drivers!I18 -> 26312 | J7: =Drivers!J18 -> 28336 | K7: =Drivers!K18 -> 30816.905 | ... O7: =Drivers!O18 -> 37111.444
B8: COGS | D8: -6428 | E8: -6777 | F8: -6961 | G8: -7094 | H8: -7873 | I8: -9085 | J8: =-J7*J40 -> -9820.5344 | K8: =-K7*K40 -> -10656.796 | L8: =-L7*L40 -> -11144.338 | M8: =-M7*M40 -> -11519.751 | N8: =-N7*N40 -> -12101.148 | O8: =-O7*O40 -> -12802.448
B9: Gross Profit | D9: =SUM(D7:D8) -> 11877 | E9: =SUM(E7:E8) -> 12500 | F9: =SUM(F7:F8) -> 12560 | G9: =SUM(G7:G8) -> 14164 | H9: =SUM(H7:H8) -> 15205 | I9: =SUM(I7:I8) -> 17227 | J9: =SUM(J7:J8) -> 18515.466 | K9: =SUM(K7:K8) -> 20160.109 | ... O9: =SUM(O7:O8) -> 24308.996
B11: Operating Costs | D11: -9636 | E11: -10234 | F11: -10061 | G11: -11408 | H11: -12257 | I11: -13924 | J11: -14841 | K11: =-K7*K41 -> -16259.857 | L11: =-L7*L41 -> -17056.583 | M11: =-M7*M41 -> -17716.921 | N11: =-N7*N41 -> -18588.42 | O11: =-O7*O41 -> -19594.36
B12: Operating Income | D12: =SUM(D9:D11) -> 2241 | E12: =SUM(E9:E11) -> 2266 | F12: =SUM(F9:F11) -> 2499 | G12: =SUM(G9:G11) -> 2756 | H12: =SUM(H9:H11) -> 2948 | I12: =SUM(I9:I11) -> 3303 | J12: =SUM(J9:J11) -> 3674.4656 | K12: =SUM(K9:K11) -> 3900.2522 | ... O12: =SUM(O9:O11) -> 4714.6361
B14: add: Other Income | D14: 318 | E14: 339 | F14: 611 | G14: 395 | H14: 412 | I14: 479 | J14: 427 | K14: =K7*K42 -> 598.57518 | L14: =L7*L42 -> 637.16878 | M14: =M7*M42 -> 672.61759 | N14: =N7*N42 -> 646.81456 | O14: =O7*O42 -> 682.30671
B16: EBITDA | D16: =D12+D14 -> 2559 | E16: =E12+E14 -> 2605 | F16: =F12+F14 -> 3110 | G16: =G12+G14 -> 3151 | H16: =H12+H14 -> 3360 | I16: =I12+I14 -> 3782 | J16: =J12+J14 -> 4101.4656 | K16: =K12+K14 -> 4498.8273 | ... O16: =O12+O14 -> 5396.9428
B18: less: D&A | D18: =-(D19+D20) -> -660 | E18: =-(E19+E20) -> -675 | F18: =-(F19+F20) -> -720 | G18: =-(G19+G20) -> -767 | H18: =-(H19+H20) -> -787 | I18: =-(I19+I20) -> -1097 | J18: =-(J19+J20) -> -1176 | K18: =-(K19+K20) -> -1150.4882 | ... O18: =-(O19+O20) -> -1421.0011
B19: Depreciation | D19: 511 | E19: 543 | F19: 513 | G19: 549 | H19: 564 | I19: 663 | J19: 745 | K19: =K$7*K43 -> 810.56054 | L19: =L$7*L43 -> 842.54975 | M19: =M$7*M43 -> 865.84044 | N19: =N$7*N43 -> 902.95196 | O19: =O$7*O43 -> 953.1023
B20: Amortization | D20: 149 | E20: 132 | F20: 207 | G20: 218 | H20: 223 | I20: 434 | J20: 431 | K20: =K$7*K44 -> 339.92768 | L20: =L$7*L44 -> 369.81207 | M20: =M$7*M44 -> 406.50851 | N20: =N$7*N44 -> 432.63597 | O20: =O$7*O44 -> 467.89879
B21: EBIT | D21: =D16+D18 -> 1899 | E21: =E16+E18 -> 1930 | F21: =F16+F18 -> 2390 | G21: =G16+G18 -> 2384 | H21: =H16+H18 -> 2573 | I21: =I16+I18 -> 2685 | J21: =J16+J18 -> 2925.4656 | K21: =K16+K18 -> 3348.3391 | ... O21: =O16+O18 -> 3975.9418
B23: Net Finance Cost | D23: =SUM(D24:D25) -> -273 | E23: =SUM(E24:E25) -> -334 | F23: =SUM(F24:F25) -> -279 | G23: =SUM(G24:G25) -> -395 | H23: =SUM(H24:H25) -> -247 | I23: =SUM(I24:I25) -> -353 | J23: =SUM(J24:J25) -> -353 | K23: =SUM(K24:K25) -> -447.68274 | ... O23: =SUM(O24:O25) -> -496.61068
B24: Finance Income | D24: 27 | E24: 17 | F24: 32 | G24: 47 | H24: 172 | I24: 135 | J24: 135 | K24: =K$7*K45 -> 103.69916 | L24: =L$7*L45 -> 117.47003 | M24: =M$7*M45 -> 135.33323 | N24: =N$7*N45 -> 153.52259 | O24: =O$7*O45 -> 173.60691
B25: Finance Cost | D25: -300 | E25: -351 | F25: -311 | G25: -442 | H25: -419 | I25: -488 | J25: -488 | K25: =-K$7*K46 -> -551.3819 | L25: =-L$7*L46 -> -585.1491 | M25: =-M$7*M46 -> -607.82559 | N25: =-N$7*N46 -> -646.51007 | O25: =-O$7*O46 -> -670.21759
B26: EBT | D26: =D21+D23 -> 1626 | E26: =E21+E23 -> 1596 | F26: =F21+F23 -> 2111 | G26: =G21+G23 -> 1989 | H26: =H21+H23 -> 2326 | I26: =I21+I23 -> 2332 | J26: =J21+J23 -> 2572.4656 | K26: =K21+K23 -> 2900.6564 | ... O26: =O21+O23 -> 3479.3311
B28: less: Tax Expense | D28: -94 | E28: -225 | F28: -198 | G28: -315 | H28: -386 | I28: -291 | J28: -421 | K28: =-K29*K26 -> -580.13127 | L28: =-L29*L26 -> -614.5007 | M28: =-M29*M26 -> -657.32277 | N28: =-N29*N26 -> -652.57251 | O28: =-O29*O26 -> -695.86622
B29: Effective Tax Rate | D29: =-D28/D26 -> 0.057810578 | E29: =-E28/E26 -> 0.14097744 | F29: =-F28/F26 -> 0.09379441 | G29: =-G28/G26 -> 0.15837104 | H29: =-H28/H26 -> 0.16595013 | I29: =-I28/I26 -> 0.12478559 | J29: =-J28/J26 -> 0.16365622 | K29: 0.2 | L29: 0.2 | M29: 0.2 | N29: 0.2 | O29: 0.2
B30: PAT | D30: =D26+D28 -> 1532 | E30: =E26+E28 -> 1371 | F30: =F26+F28 -> 1913 | G30: =G26+G28 -> 1674 | H30: =H26+H28 -> 1940 | I30: =I26+I28 -> 2041 | J30: =J26+J28 -> 2151.4656 | K30: =K26+K28 -> 2320.5251 | ... O30: =O26+O28 -> 2783.4649
B32: less: Minority Interest | D32: -56 | E32: -72 | F32: -154 | G32: -83 | H32: -83 | I32: -85 | J32: -89 | K32: -89 | L32: -89 | M32: -89 | N32: -89 | O32: -89
B33: Net Income to Common Shareholders | D33: =D30+D32 -> 1476 | E33: =E30+E32 -> 1299 | F33: =F30+F32 -> 1759 | G33: =G30+G32 -> 1591 | H33: =H30+H32 -> 1857 | I33: =I30+I32 -> 1956 | J33: =J30+J32 -> 2062.4656 | K33: =K30+K32 -> 2231.5251 | ... O33: =O30+O32 -> 2694.4649
B35: Shares O/S | D35: 3205.1 | E35: 3218 | F35: 3167.2 | G35: 3076.9 | H35: 3035 | I35: 3013 | J35: 2997 | K35: =J35*(1+K48) -> 2963.8087 | L35: =K35*(1+L48) -> 2923.5262 | M35: =L35*(1+M48) -> 2884.8607 | N35: =M35*(1+N48) -> 2854.0558 | O35: =N35*(1+O48) -> 2824.9781
B36: EPS | D36: =D33/D35 -> 0.46051605 | E36: =E33/E35 -> 0.40366687 | F36: =F33/F35 -> 0.55538015 | G36: =G33/G35 -> 0.51707888 | H36: =H33/H35 -> 0.61186161 | I36: =I33/I35 -> 0.64918686 | J36: =J33/J35 -> 0.6881767 | K36: =K33/K35 -> 0.75292481 | ... O36: =O33/O35 -> 0.95380025
B38: Drivers
B40: COGS as % of Revenue | D40: =-D8/D7 -> 0.35116089 | E40: =-E8/E7 -> 0.35155885 | F40: =-F8/F7 -> 0.35659034 | G40: =-G8/G7 -> 0.33370966 | H40: =-H8/H7 -> 0.34114741 | I40: =-I8/I7 -> 0.34527972 | J40: =AVERAGE(D40:I40) -> 0.34657448 | K40: =AVERAGE(E40:J40) -> 0.34581008 | L40: =AVERAGE(F40:K40) -> 0.34485195 | M40: =AVERAGE(G40:L40) -> 0.34289555 | N40: =AVERAGE(H40:M40) -> 0.34442653 | O40: =AVERAGE(I40:N40) -> 0.34497305
B41: Operating Cost as % of Revenue | D41: =-D11/D7 -> 0.52641355 | E41: =-E11/E7 -> 0.53089174 | F41: =-F11/F7 -> 0.51539368 | G41: =-G11/G7 -> 0.53664503 | H41: =-H11/H7 -> 0.53111188 | I41: =-I11/I7 -> 0.5291882 | J41: =-J11/J7 -> 0.52375071 | K41: =AVERAGE(D41:J41) -> 0.52762783 | L41: =AVERAGE(E41:K41) -> 0.52780129 | M41: =AVERAGE(F41:L41) -> 0.5273598 | N41: =AVERAGE(G41:M41) -> 0.52906925 | O41: =AVERAGE(H41:N41) -> 0.52798699
B42: Other Income as % of Revenue | D42: =D14/D7 -> 0.017372303 | E42: =E14/E7 -> 0.017585724 | F42: =F14/F7 -> 0.031299626 | G42: =G14/G7 -> 0.01858124 | H42: =H14/H7 -> 0.0178525 | I42: =I14/I7 -> 0.018204621 | J42: =J14/J7 -> 0.01506917 | K42: =AVERAGE(D42:J42) -> 0.019423598 | L42: =AVERAGE(E42:K42) -> 0.01971664 | M42: =AVERAGE(F42:L42) -> 0.020021056 | N42: =AVERAGE(G42:M42) -> 0.018409832 | O42: =AVERAGE(H42:N42) -> 0.018385345
B43: Depreciation as % of Revenue | D43: =D19/D$7 -> 0.02791587 | E43: =E19/E$7 -> 0.028168283 | F43: =F19/F$7 -> 0.026279391 | G43: =G19/G$7 -> 0.025825572 | H43: =H19/H$7 -> 0.02443886 | I43: =I19/I$7 -> 0.025197628 | J43: =J19/J$7 -> 0.026291643 | K43: =AVERAGE(D43:J43) -> 0.026302464 | L43: =AVERAGE(E43:K43) -> 0.026071977 | M43: =AVERAGE(F43:L43) -> 0.025772505 | N43: =AVERAGE(G43:M43) -> 0.025700093 | O43: =AVERAGE(H43:N43) -> 0.025682167
B44: Amortization as % of Revenue | D44: =D20/D$7 -> 0.0081398525 | E44: =E20/E$7 -> 0.0068475385 | F44: =F20/F$7 -> 0.010603965 | G44: =G20/G$7 -> 0.010254963 | H44: =H20/H$7 -> 0.0096628824 | I44: =I20/I$7 -> 0.016494375 | J44: =J20/J$7 -> 0.015210333 | K44: =AVERAGE(D44:J44) -> 0.011030559 | L44: =AVERAGE(E44:K44) -> 0.011443517 | M44: =AVERAGE(F44:L44) -> 0.012100085 | N44: =AVERAGE(G44:M44) -> 0.012313816 | O44: =AVERAGE(H44:N44) -> 0.012607938
B45: Finance Income as % of Revenue | D45: =D24/D$7 -> 0.0014750068 | E45: =E24/E$7 -> 0.00088187996 | F45: =F24/F$7 -> 0.0016392603 | G45: =G24/G$7 -> 0.0022109324 | H45: =H24/H$7 -> 0.0074529855 | I45: =I24/I$7 -> 0.0051307388 | J45: =J24/J$7 -> 0.0047642575 | K45: =AVERAGE(D45:J45) -> 0.0033650088 | L45: =AVERAGE(E45:K45) -> 0.003635009 | M45: =AVERAGE(F45:L45) -> 0.0040283132 | N45: =AVERAGE(G45:M45) -> 0.0043696064 | O45: =AVERAGE(H45:N45) -> 0.0046779885
B46: Finance Cost as % of Revenue | D46: =-D25/D$7 -> 0.016388965 | E46: =-E25/E$7 -> 0.018208227 | F46: =-F25/F$7 -> 0.015931561 | G46: =-G25/G$7 -> 0.020792172 | H46: =-H25/H$7 -> 0.018155819 | I46: =-I25/I$7 -> 0.018546671 | J46: =-J25/J$7 -> 0.017221909 | K46: =AVERAGE(D46:J46) -> 0.017892189 | L46: =AVERAGE(E46:K46) -> 0.018106935 | M46: =AVERAGE(F46:L46) -> 0.018092465 | N46: =AVERAGE(G46:M46) -> 0.018401166 | O46: =AVERAGE(H46:N46) -> 0.018059593
B48: Shares O/S degrowth | E48: =E35/D35-1 -> 0.0040248354 | F48: =F35/E35-1 -> -0.015786203 | G48: =G35/F35-1 -> -0.028510988 | H48: =H35/G35-1 -> -0.013617602 | I48: =I35/H35-1 -> -0.0072487644 | J48: =J35/I35-1 -> -0.0053103219 | K48: =AVERAGE(E48:J48) -> -0.011074841 | L48: =AVERAGE(F48:K48) -> -0.013591453 | M48: =AVERAGE(G48:L48) -> -0.013225662 | N48: =AVERAGE(H48:M48) -> -0.010678107 | O48: =AVERAGE(I48:N48) -> -0.010188192
B50: Capex | D50: 360 | E50: 385 | F50: 366 | G50: 599 | H50: 826 | I50: 990 | J50: 920 | K50: =K51*J7 -> 779.0377 | L50: =L51*K7 -> 881.69864 | M50: =M51*L7 -> 964.47995 | N50: =N51*M7 -> 1055.9116 | O50: =O51*N7 -> 1120.5975
B51: Capex as % of Revenue | D51: =D50/D$7 -> 0.019666758 | E51: =E50/E$7 -> 0.019971987 | F51: =F50/F$7 -> 0.018749039 | G51: =G50/G$7 -> 0.028177627 | H51: =H50/H$7 -> 0.035791663 | I51: =I50/I$7 -> 0.037625418 | J51: =J50/J$7 -> 0.032467532 | K51: =AVERAGE(D51:J51) -> 0.027492861 | L51: =AVERAGE(E51:K51) -> 0.028610875 | M51: =AVERAGE(F51:L51) -> 0.029845002 | N51: =AVERAGE(G51:M51) -> 0.03143014 | O51: =AVERAGE(H51:N51) -> 0.031894785

Sheet WACC
B2: ="Exihibit "&VLOOKUP(B3,TOC!$B$7:$D$10,3,FALSE) -> Exihibit 3
B3: Weighted Average Cost of Capital
B5: Cost of Equity | E5: Weights | K5: Beta Calculation
B6: Risk-Free Rate | C6: 0.04518 | E6: Capital Source | F6: in £ bn. | G6: % terms
B7: Beta | C7: =M26 -> 0.61360476 | E7: Market Cap. | F7: 66.7188 | G7: =F7/$F$9 -> 0.88054608 | K7: Company | M7: Levered Beta | N7: Tax Rate | O7: Debt/Equity | P7: Unlevered Beta
B8: Market Return | C8: 0.12305 | E8: Debt | F8: 9.051 | G8: =F8/$F$9 -> 0.11945392 | K8: SAAB AB | M8: 0.529 | N8: 0.2074 | O8: 0.3368 | P8: =M8/(1+(O8*(1-N8))) -> 0.41753895
B9: Equity Risk Premium | C9: =C8-C6 -> 0.07787 | E9: Total Capital | F9: =SUM(F7:F8) -> 75.7698 | G9: =SUM(G7:G8) -> 1 | K9: Rheinmetall AG | M9: 0.547 | N9: 0.2718 | O9: 0.5427 | P9: =M9/(1+(O9*(1-N9))) -> 0.39206013
B10: Cost of Equity | C10: =C6+(C7*C9) -> 0.092961402 | K10: Lockheed Martin | M10: 0.583 | N10: 0.1528 | O10: 3.3924 | P10: =M10/(1+(O10*(1-N10))) -> 0.15048885
E11: WACC Calculation | K11: Northrop Grumman Corp | M11: 0.535 | N11: 0.1748 | O11: 1.0726 | P11: =M11/(1+(O11*(1-N11))) -> 0.28380314
B12: Cost of Debt | E12: Source | F12: Weight | G12: Cost | K12: L3Harris Technologies Inc | M12: 0.77 | N12: 0.1687 | O12: 0.5718 | P12: =M12/(1+(O12*(1-N12))) -> 0.52191453
B13: Weighted Average Kd | C13: =AVERAGE(E39,I23) -> 0.047211719 | E13: Equity | F13: =G7 -> 0.88054608 | G13: =C10 -> 0.092961402 | K13: Average | M13: =AVERAGE(M8:M12) -> 0.5928 | N13: =AVERAGE(N8:N12) -> 0.1951 | O13: =AVERAGE(O8:O12) -> 1.18326 | P13: =AVERAGE(P8:P12) -> 0.35316112
B14: w/ Method 1 & 2 | E14: Debt | F14: =G8 -> 0.11945392 | G14: =C13 -> 0.047211719
E15: WACC | G15: =SUMPRODUCT(F13:F14,G13:G14) -> 0.087496423 | K15: BAE Systems Beta
K16: Method 1: Relative Beta
K17: Effective Tax Rate | M17: 0.35
B18: Method 1: Weighted Average Yield | G18: Method 2: Credit Rating Method | K18: D/E Ratio | M18: 0.7582
K19: Peer's Avg. Unlevered Beta | M19: =P13 -> 0.35316112
B20: Security ID | C20: Yield | D20: Amount | E20: Weights | G20: Risk-Free Rate | I20: 0.0452
B21: ZD865113 Corp | C21: 0.038944306 | D21: 800000000 | E21: =D21/SUM($D$21:$D$38) -> 0.047058824 | G21: Interest Coverage Ratio | I21: 8.29 | K21: BAE Systmes Levered Beta | M21: =M19*(1+(M18*(1-M17))) -> 0.52720951
B22: ZD865131 Corp | C22: 0.038944306 | D22: 800000000 | E22: =D22/SUM($D$21:$D$38) -> 0.047058824 | G22: Spread Associated with ICR [1] | I22: 0.004
B23: ZD865117 Corp | C23: 0.04020528 | D23: 1250000000 | E23: =D23/SUM($D$21:$D$38) -> 0.073529412 | G23: Cost of Debt | I23: =I20+I22 -> 0.0492 | K23: Method 2: Regression Beta
B24: ZD865135 Corp | C24: 0.04020528 | D24: 1250000000 | E24: =D24/SUM($D$21:$D$38) -> 0.073529412 | K24: 5yr Regression Adj. Beta [2] | M24: 0.7
B25: BH632720 Corp | C25: 0.041443469 | D25: 1300000000 | E25: =D25/SUM($D$21:$D$38) -> 0.076470588
B26: BH632721 Corp | C26: 0.041443469 | D26: 1300000000 | E26: =D26/SUM($D$21:$D$38) -> 0.076470588 | K26: Average Beta | M26: =AVERAGE(M24,M21) -> 0.61360476
B27: ZO394550 Corp | C27: 0.043167151 | D27: 1000000000 | E27: =D27/SUM($D$21:$D$38) -> 0.058823529
B28: ZO394548 Corp | C28: 0.043167151 | D28: 1000000000 | E28: =D28/SUM($D$21:$D$38) -> 0.058823529
B29: ZD865119 Corp | C29: 0.043381216 | D29: 500000000 | E29: =D29/SUM($D$21:$D$38) -> 0.029411765
B30: ZD865138 Corp | C30: 0.043381216 | D30: 500000000 | E30: =D30/SUM($D$21:$D$38) -> 0.029411765
B31: ZD865122 Corp | C31: 0.045972969 | D31: 1500000000 | E31: =D31/SUM($D$21:$D$38) -> 0.088235294 | G31: Notes:
B32: ZD865142 Corp | C32: 0.045972969 | D32: 1500000000 | E32: =D32/SUM($D$21:$D$38) -> 0.088235294 | G32: [1] ICR: Interest Coverage Ratio
B33: EI835105 Corp | C33: 0.052789739 | D33: 400000000 | E33: =D33/SUM($D$21:$D$38) -> 0.023529412 | G33: [2] Regression Beta From Bloomberg Terminal
B34: EI835901 Corp | C34: 0.052789739 | D34: 400000000 | E34: =D34/SUM($D$21:$D$38) -> 0.023529412
B35: ZO394553 Corp | C35: 0.053722709 | D35: 1000000000 | E35: =D35/SUM($D$21:$D$38) -> 0.058823529
B36: ZO394551 Corp | C36: 0.053722709 | D36: 1000000000 | E36: =D36/SUM($D$21:$D$38) -> 0.058823529
B37: ZD865127 Corp | C37: 0.0539398 | D37: 750000000 | E37: =D37/SUM($D$21:$D$38) -> 0.044117647
B38: ZD865145 Corp | C38: 0.0539398 | D38: 750000000 | E38: =D38/SUM($D$21:$D$38) -> 0.044117647
B39: Weighted Average Yield | E39: =SUMPRODUCT(C21:C38,E21:E38) -> 0.045223438

Sheet DCF
B2: ="Exihibit "&VLOOKUP(B3,TOC!$B$7:$D$10,3,FALSE) -> Exihibit 4
B3: Discounted Cash Flow
B6: Fiscal Year ending December | C6: 2025 | D6: 2026 | E6: =D6+1 -> 2027 | F6: =E6+1 -> 2028 | G6: =F6+1 -> 2029 | H6: =G6+1 -> 2030
B8: CFO | C8: =J39 -> 3298 | D8: =K39 -> 3491.7957 | E8: =L39 -> 3661.6885 | F8: =M39 -> 3806.6333 | G8: =N39 -> 3980.9779 | H8: =O39 -> 4205.016
B9: add: Interest (1-t) | C9: =-IS!J23*(1-IS!J29) -> 295.22935 | D9: =-IS!K23*(1-IS!K29) -> 358.1462 | E9: =-IS!L23*(1-IS!L29) -> 374.14325 | F9: =-IS!M23*(1-IS!M29) -> 377.99388 | G9: =-IS!N23*(1-IS!N29) -> 394.38999 | H9: =-IS!O23*(1-IS!O29) -> 397.28855
B10: less: Capex | C10: =-IS!J50 -> -920 | D10: =-IS!K50 -> -779.0377 | E10: =-IS!L50 -> -881.69864 | F10: =-IS!M50 -> -964.47995 | G10: =-IS!N50 -> -1055.9116 | H10: =-IS!O50 -> -1120.5975
B11: FCFF | C11: =SUM(C8:C10) -> 2673.2294 | D11: =SUM(D8:D10) -> 3070.9042 | E11: =SUM(E8:E10) -> 3154.1331 | F11: =SUM(F8:F10) -> 3220.1472 | G11: =SUM(G8:G10) -> 3319.4563 | H11: =SUM(H8:H10) -> 3481.7071
B13: Shares O/S | C13: =IS!J35 -> 2997 | D13: =IS!K35 -> 2963.8087 | E13: =IS!L35 -> 2923.5262 | F13: =IS!M35 -> 2884.8607 | G13: =IS!N35 -> 2854.0558 | H13: =IS!O35 -> 2824.9781
B14: FCFF/Share | C14: =C11/C13 -> 0.89196842 | D14: =D11/D13 -> 1.0361344 | E14: =E11/E13 -> 1.0788797 | F14: =F11/F13 -> 1.1162228 | G14: =G11/G13 -> 1.1630663 | H14: =H11/H13 -> 1.2324722
B16: Today's Date | C16: =TODAY() -> 46128
B17: Next CF Ending Date | C17: 46387
B19: Effective Date | D19: 46387 | E19: 46752 | F19: 47118 | G19: 47483 | H19: 47848
B20: Period | D20: =_xlfn.DAYS(D19,$C$16)/365 -> 0.70958904 | E20: =_xlfn.DAYS(E19,$C$16)/365 -> 1.709589 | F20: =_xlfn.DAYS(F19,$C$16)/365 -> 2.7123288 | G20: =_xlfn.DAYS(G19,$C$16)/365 -> 3.7123288 | H20: =_xlfn.DAYS(H19,$C$16)/365 -> 4.7123288
B21: Discounting Factor | D21: =1/(1+WACC!$G$15)^DCF!D20 -> 0.94221759 | E21: =1/(1+WACC!$G$15)^DCF!E20 -> 0.86640983 | F21: =1/(1+WACC!$G$15)^DCF!F20 -> 0.79651825 | G21: =1/(1+WACC!$G$15)^DCF!G20 -> 0.73243298 | H21: =1/(1+WACC!$G$15)^DCF!H20 -> 0.67350381
B23: PV of FCFF/Share | D23: =D21*D14 -> 0.97626408 | E23: =E21*E14 -> 0.93475196 | F23: =F21*F14 -> 0.88909181 | G23: =G21*G14 -> 0.85186815 | H23: =H21*H14 -> 0.83007474
B25: Equity Value Calculation | F25: Terminal Value Calculation
B26: Sum of PV of FCFF/Share | C26: =SUM(D14:H14) -> 5.6267755 | F26: Method 1: Multiples Method
B27: Average Terminal Value | C27: =AVERAGE(H29,H35) -> 85155.354 | F27: Exit EBITDA | H27: =IS!O16 -> 5396.9428
B28: EV/Share | C28: =C27/C13 -> 28.413532 | F28: Exit EV/EBITDA Multiple | H28: 20
B29: less: Debt/share | C29: =-WACC!F8/(DCF!C13/1000) -> -3.02002 | F29: Exit EV | H29: =H27*H28 -> 107938.86
B30: add: Cash/share | C30: =3621/C13 -> 1.2082082
B31: Equity Value | C31: =SUM(C28:C30,C26) -> 32.228495 | F31: Method 2: GGM Method
F32: FCFF at Terminal Year | H32: =H11 -> 3481.7071
F33: Perpetual Growth Rate | H33: 0.03
F34: WACC | H34: =WACC!G15 -> 0.087496423
F35: TV using GGM | H35: =H32*(1+H33)/(H34-H33) -> 62371.851
B37: Driver
B38: FYE | D38: 2019 | E38: =D38+1 -> 2020 | F38: =E38+1 -> 2021 | G38: =F38+1 -> 2022 | H38: =G38+1 -> 2023 | I38: =H38+1 -> 2024 | J38: =I38+1 -> 2025 | K38: =J38+1 -> 2026 | L38: =K38+1 -> 2027 | ... O38: =N38+1 -> 2030
B39: Cash from Operating Activities | D39: 1534 | E39: 985 | F39: 2280 | G39: 2696 | H39: 3664 | I39: 3670 | J39: 3298 | K39: =IS!K7*K40 -> 3491.7957 | L39: =IS!L7*L40 -> 3661.6885 | M39: =IS!M7*M40 -> 3806.6333 | N39: =IS!N7*N40 -> 3980.9779 | O39: =IS!O7*O40 -> 4205.016
B40: CFO as % of Revenue | D40: =D39/IS!D7 -> 0.08380224 | E40: =E39/IS!E7 -> 0.051097162 | F40: =F39/IS!F7 -> 0.1167973 | G40: =G39/IS!G7 -> 0.12682284 | H40: =H39/IS!H7 -> 0.15876592 | I40: =I39/IS!I7 -> 0.13948009 | J40: =J39/IS!J7 -> 0.11638905 | K40: =AVERAGE($D$40:$J$40) -> 0.1133078 | L40: =AVERAGE($D$40:$J$40) -> 0.1133078 | M40: =AVERAGE($D$40:$J$40) -> 0.1133078 | N40: =AVERAGE($D$40:$J$40) -> 0.1133078 | O40: =AVERAGE($D$40:$J$40) -> 0.1133078
