Workbook
Name IQ_CH: 110000
Name IQ_CQ: 5000
Name IQ_CY: 10000
Name IQ_DAILY: 500000
Name IQ_FH: 100000
Name IQ_FQ: 500
Name IQ_FY: 1000
Name IQ_LTM: 2000
Name IQ_MONTH: 15000
Name IQ_NTM: 6000
Name IQ_WEEK: 50000
Name IQ_YTD: 3000

Sheet Inputs FS
B2: FYE ending December 31 | D2: 2021 | E2: =D2+1 -> 2022 | F2: =E2+1 -> 2023 | G2: =F2+1 -> 2024 | H2: =G2+1 -> 2025 | I2: =H2+1 -> 2026 | J2: =I2+1 -> 2027 | K2: =J2+1 -> 2028 | L2: =K2+1 -> 2029 | ... R2: =Q2+1 -> 2035
B4: Income Statement
B6: Net Sales | C6: 17858 | D6: 19628 | E6: 20752 | F6: 23196 | G6: 24878 | H6: 27448 | I6: =H6*(1+I57) -> 30249.01 | J6: =I6*(1+J57) -> 33335.858 | K6: =J6*(1+K57) -> 36737.712 | L6: =K6*(1+L57) -> 40486.717 | M6: =L6*(1+M57) -> 44618.301 | N6: =M6*(1+N57) -> 48901.35 | O6: =N6*(1+O57) -> 53299.455 | P6: =O6*(1+P57) -> 57770.401 | ... R6: =Q6*(1+R57) -> 64850.661
B7: Cost of products sold | D7: -12371 | E7: -12911 | F7: -13836 | G7: -14454 | H7: -16125 | I7: =-I6*I62 -> -17657.165 | J7: =-J6*J62 -> -19334.117 | K7: =-K6*K62 -> -21169.45 | L7: =-L6*L62 -> -23178.026 | M7: =-M6*M62 -> -25376.09 | N7: =-N6*N62 -> -27628.764 | O7: =-O6*O62 -> -29913.911 | P7: =-P6*P62 -> -32206.704 | ... R7: =-R6*R62 -> -35667.864
B8: Gross Profit | D8: =SUM(D6:D7) -> 7257 | E8: =SUM(E6:E7) -> 7841 | F8: =SUM(F6:F7) -> 9360 | G8: =SUM(G6:G7) -> 10424 | H8: =SUM(H6:H7) -> 11323 | I8: =SUM(I6:I7) -> 12591.845 | J8: =SUM(J6:J7) -> 14001.74 | K8: =SUM(K6:K7) -> 15568.261 | ... R8: =SUM(R6:R7) -> 29182.798
B10: Operating Expenses
B11: Selling & administrative expense | D11: -2829 | E11: -3000 | F11: -3684 | G11: -3839 | H11: -3995 | I11: =-I6*I63 -> -4521.4811 | J11: =-J6*J63 -> -4982.8886 | K11: =-K6*K63 -> -5491.3819 | L11: =-L6*L63 -> -6051.7658 | M11: =-M6*M63 -> -6669.3357 | N11: =-N6*N63 -> -7309.5459 | O11: =-O6*O63 -> -7966.954 | P11: =-P6*P63 -> -8635.2502 | ... R11: =-R6*R63 -> -9693.5746
B12: R&D Expense | D12: -616 | E12: -665 | F12: -754 | G12: -794 | H12: -797 | I12: =-VLOOKUP(I$2,'R&D_Cap'!$A$4:$F$29,3,FALSE) -> -891.76723 | J12: =-VLOOKUP(J$2,'R&D_Cap'!$A$4:$F$29,3,FALSE) -> -990.54399 | K12: =-VLOOKUP(K$2,'R&D_Cap'!$A$4:$F$29,3,FALSE) -> -1098.4839 | L12: =-VLOOKUP(L$2,'R&D_Cap'!$A$4:$F$29,3,FALSE) -> -1212.4418 | M12: =-VLOOKUP(M$2,'R&D_Cap'!$A$4:$F$29,3,FALSE) -> -1339.9091 | N12: =-VLOOKUP(N$2,'R&D_Cap'!$A$4:$F$29,3,FALSE) -> -1468.7321 | O12: =-VLOOKUP(O$2,'R&D_Cap'!$A$4:$F$29,3,FALSE) -> -1601.9238 | P12: =-VLOOKUP(P$2,'R&D_Cap'!$A$4:$F$29,3,FALSE) -> -1741.819 | ... R12: =-VLOOKUP(R$2,'R&D_Cap'!$A$4:$F$29,3,FALSE) -> -1977.5723
B13: Operating Profit | D13: =SUM(D8:D12) -> 3812 | E13: =SUM(E8:E12) -> 4176 | F13: =SUM(F8:F12) -> 4922 | G13: =SUM(G8:G12) -> 5791 | H13: =SUM(H8:H12) -> 6531 | I13: =SUM(I8:I12) -> 7178.5966 | J13: =SUM(J8:J12) -> 8028.3078 | K13: =SUM(K8:K12) -> 8978.3953 | ... R13: =SUM(R8:R12) -> 17511.651
B15: Gain on sale of business | D15: 617 | E15: 24 | F15: 0 | G15: 0 | H15: 0 | I15: 0 | J15: 0 | K15: 0 | L15: 0 | M15: 0 | N15: 0 | O15: 0 | P15: 0 | Q15: 0 | R15: 0
B16: Other Income (expense) - net | D16: -40 | E16: 36 | F16: 93 | G16: 64 | H16: -37
B17: Restructuring Charges | D17: -78 | E17: -33 | F17: -57 | G17: -202 | H17: -133
B18: Acquisition & Divestiture Charges | D18: -349 | E18: -194 | F18: -54 | G18: -36 | H18: -183
B19: EBITDA | D19: =SUM(D13:D18) -> 3962 | E19: =SUM(E13:E18) -> 4009 | F19: =SUM(F13:F18) -> 4904 | G19: =SUM(G13:G18) -> 5617 | H19: =SUM(H13:H18) -> 6178 | I19: =SUM(I13:I18) -> 7178.5966 | J19: =SUM(J13:J18) -> 8028.3078 | K19: =SUM(K13:K18) -> 8978.3953 | ... R19: =SUM(R13:R18) -> 17511.651
B21: Depreciation | D21: -426 | E21: -408 | F21: -429 | G21: -446 | H21: -477 | I21: =-I$6*I60 -> -575.72829 | J21: =-J$6*J60 -> -616.67395 | K21: =-K$6*K60 -> -671.06684 | L21: =-L$6*L60 -> -737.70048 | M21: =-M$6*M60 -> -815.5987 | N21: =-N$6*N60 -> -902.70404 | O21: =-O$6*O60 -> -977.78075 | P21: =-P$6*P60 -> -1058.0237 | ... R21: =-R$6*R60 -> -1189.651
B22: Amortization | D22: -496 | E22: -546 | F22: -497 | G22: -475 | H22: -529 | I22: =-I$6*I61 -> -673.78357 | J22: =-J$6*J61 -> -722.57054 | K22: =-K$6*K61 -> -762.24969 | L22: =-L$6*L61 -> -834.54823 | M22: =-M$6*M61 -> -933.27353 | N22: =-N$6*N61 -> -1038.9404 | O22: =-O$6*O61 -> -1121.4126 | P22: =-P$6*P61 -> -1208.1366 | ... R22: =-R$6*R61 -> -1362.6504
B23: Depreciation & Amortization Expense | D23: =SUM(D21:D22) -> -922 | E23: =SUM(E21:E22) -> -954 | F23: =SUM(F21:F22) -> -926 | G23: =SUM(G21:G22) -> -921 | H23: =SUM(H21:H22) -> -1006 | I23: =SUM(I21:I22) -> -1249.5119 | J23: =SUM(J21:J22) -> -1339.2445 | K23: =SUM(K21:K22) -> -1433.3165 | ... R23: =SUM(R21:R22) -> -2552.3014
B24: EBIT | D24: =SUM(D19,D23) -> 3040 | E24: =SUM(E19,E23) -> 3055 | F24: =SUM(F19,F23) -> 3978 | G24: =SUM(G19,G23) -> 4696 | H24: =SUM(H19,H23) -> 5172 | I24: =SUM(I19,I23) -> 5929.0847 | J24: =SUM(J19,J23) -> 6689.0633 | K24: =SUM(K19,K23) -> 7545.0788 | ... R24: =SUM(R19,R23) -> 14959.349
B26: Amortization expense for R&D | D26: =VLOOKUP(D$2,'R&D_Cap'!$A$4:$F$24,6,FALSE) -> 568.4 | E26: =VLOOKUP(E$2,'R&D_Cap'!$A$4:$F$24,6,FALSE) -> 588.3 | F26: =VLOOKUP(F$2,'R&D_Cap'!$A$4:$F$24,6,FALSE) -> 610.9 | G26: =VLOOKUP(G$2,'R&D_Cap'!$A$4:$F$24,6,FALSE) -> 621.9 | H26: =VLOOKUP(H$2,'R&D_Cap'!$A$4:$F$24,6,FALSE) -> 636.6 | I26: =VLOOKUP(I$2,'R&D_Cap'!$A$4:$F$29,6,FALSE) -> 653.8 | J26: =VLOOKUP(J$2,'R&D_Cap'!$A$4:$F$29,6,FALSE) -> 684.27672 | K26: =VLOOKUP(K$2,'R&D_Cap'!$A$4:$F$29,6,FALSE) -> 724.93112 | L26: =VLOOKUP(L$2,'R&D_Cap'!$A$4:$F$29,6,FALSE) -> 776.37952 | M26: =VLOOKUP(M$2,'R&D_Cap'!$A$4:$F$29,6,FALSE) -> 837.02369 | N26: =VLOOKUP(N$2,'R&D_Cap'!$A$4:$F$29,6,FALSE) -> 915.9146 | O26: =VLOOKUP(O$2,'R&D_Cap'!$A$4:$F$29,6,FALSE) -> 1001.1878 | P26: =VLOOKUP(P$2,'R&D_Cap'!$A$4:$F$29,6,FALSE) -> 1094.8802 | ... R26: =VLOOKUP(R$2,'R&D_Cap'!$A$4:$F$29,6,FALSE) -> 1303.2975
B27: Adjustement amount for R&D | D27: =-(D12+D26) -> 47.6 | E27: =-(E12+E26) -> 76.7 | F27: =-(F12+F26) -> 143.1 | G27: =-(G12+G26) -> 172.1 | H27: =-(H12+H26) -> 160.4 | I27: =-(I12+I26) -> 237.96723 | J27: =-(J12+J26) -> 306.26727 | K27: =-(K12+K26) -> 373.5528 | ... R27: =-(R12+R26) -> 674.27475
B28: Adjusted EBIT | D28: =D24+D27 -> 3087.6 | E28: =E24+E27 -> 3131.7 | F28: =F24+F27 -> 4121.1 | G28: =G24+G27 -> 4868.1 | H28: =H24+H27 -> 5332.4 | I28: =I24+I27 -> 6167.0519 | J28: =J24+J27 -> 6995.3306 | K28: =K24+K27 -> 7918.6316 | ... R28: =R24+R27 -> 15633.624
B30: Interest Expense (net) | D30: -144 | E30: -144 | F30: -151 | G30: -130 | H30: -241 | I30: =-I51*I6 -> -210.47885 | J30: =-J51*J6 -> -231.95777 | K30: =-K51*K6 -> -255.62857 | L30: =-L51*L6 -> -281.71493 | M30: =-M51*M6 -> -310.46334 | N30: =-N51*N6 -> -340.26568 | O30: =-O51*O6 -> -370.8686 | P30: =-P51*P6 -> -401.97836 | ... R30: =-R51*R6 -> -451.24427
B31: Adjusted PBT | D31: =SUM(D28:D30) -> 2943.6 | E31: =SUM(E28:E30) -> 2987.7 | F31: =SUM(F28:F30) -> 3970.1 | G31: =SUM(G28:G30) -> 4738.1 | H31: =SUM(H28:H30) -> 5091.4 | I31: =SUM(I28:I30) -> 5956.5731 | J31: =SUM(J28:J30) -> 6763.3728 | K31: =SUM(K28:K30) -> 7663.003 | ... R31: =SUM(R28:R30) -> 15182.38
B33: Income tax expense | D33: -750 | E33: -445 | F33: -604 | G33: -768 | H33: -841 | I33: =-I48*I31 -> -1209.6451 | J33: =-J48*J31 -> -1408.7496 | K33: =-K48*K31 -> -1636.0865 | L33: =-L48*L31 -> -1886.7909 | M33: =-M48*M31 -> -2166.8804 | N33: =-N48*N31 -> -2466.8006 | O33: =-O48*O31 -> -2799.968 | P33: =-P48*P31 -> -3154.0777 | ... R33: =-R48*R31 -> -3795.595
B34: Adjusted Net income | D34: =SUM(D31:D33) -> 2193.6 | E34: =SUM(E31:E33) -> 2542.7 | F34: =SUM(F31:F33) -> 3366.1 | G34: =SUM(G31:G33) -> 3970.1 | H34: =SUM(H31:H33) -> 4250.4 | I34: =SUM(I31:I33) -> 4746.928 | J34: =SUM(J31:J33) -> 5354.6232 | K34: =SUM(K31:K33) -> 6026.9166 | ... R34: =SUM(R31:R33) -> 11386.785
B36: Less net income for noncontrolling interests | D36: -2 | E36: -4 | F36: -5 | G36: -4 | H36: -3 | I36: -5 | J36: -5 | K36: -5 | L36: -5 | M36: -5 | N36: -5 | O36: -5 | P36: -5 | Q36: -5 | R36: -5
B37: Adjusted Net income attributables to ETN | D37: =SUM(D34:D36) -> 2191.6 | E37: =SUM(E34:E36) -> 2538.7 | F37: =SUM(F34:F36) -> 3361.1 | G37: =SUM(G34:G36) -> 3966.1 | H37: =SUM(H34:H36) -> 4247.4 | I37: =SUM(I34:I36) -> 4741.928 | J37: =SUM(J34:J36) -> 5349.6232 | K37: =SUM(K34:K36) -> 6021.9166 | ... R37: =SUM(R34:R36) -> 11381.785
B39: Tax Benefit for R&D Expense | D39: =-(D12+D26)*D48 -> 16.274617 | E39: =-(E12+E26)*E48 -> 13.42333 | F39: =-(F12+F26)*F48 -> 25.677312 | G39: =-(G12+G26)*G48 -> 33.292058 | H39: =-(H12+H26)*H48 -> 31.737342 | J39: =-(J12+J26)*J48 -> 63.792711 | K39: =-(K12+K26)*K48 -> 79.755246 | L39: =-(L12+L26)*L48 -> 95.374766 | M39: =-(M12+M26)*M48 -> 112.61207 | N39: =-(N12+N26)*N48 -> 126.67564 | O39: =-(O12+O26)*O48 -> 140.78795 | P39: =-(P12+P26)*P48 -> 154.98891 | Q39: =-(Q12+Q26)*Q48 -> 170.54082 | R39: =-(R12+R26)*R48 -> 168.56869
B40: Normalized EBIT | D40: =D28-D15-D16+D39 -> 2526.8746 | E40: =E28-E15-E16+E39 -> 3085.1233 | F40: =F28-F15-F16+F39 -> 4053.7773 | G40: =G28-G15-G16+G39 -> 4837.3921 | H40: =H28-H15-H16+H39 -> 5401.1373 | I40: =I6*I58 -> 6071.3582 | J40: =J6*J58 -> 6824.746 | K40: =K6*K58 -> 7671.6209 | L40: =L6*L58 -> 8623.5834 | M40: =M6*M58 -> 9693.6739 | N40: =N6*N58 -> 10836.684 | O40: =O6*O58 -> 12047.543 | P40: =P6*P58 -> 13319.296 | ... R40: =R6*R58 -> 15555.739
B42: Shares O/S | D42: 398.8 | E42: 397.8 | F42: 399.4 | G42: 392.9 | H42: 387.9 | I42: 387.9 | J42: 387.9 | K42: 387.9 | L42: 387.9 | M42: 387.9 | N42: 387.9 | O42: 387.9 | P42: 387.9 | Q42: 387.9 | R42: 387.9
B43: EPS | D43: =D37/D42 -> 5.4954865 | E43: =E37/E42 -> 6.3818502 | F43: =F37/F42 -> 8.4153731 | G43: =G37/G42 -> 10.094426 | H43: =H37/H42 -> 10.949729 | I43: =I34/I42 -> 12.237504 | J43: =J34/J42 -> 13.804133 | K43: =K34/K42 -> 15.537295 | L43: =L34/L42 -> 17.375074 | M43: =M34/M42 -> 19.359722 | N43: =N34/N42 -> 21.393181 | O43: =O34/O42 -> 23.581778 | P43: =P34/P42 -> 25.809101 | ... R43: =R34/R42 -> 29.35495
B45: Year-end Share Price | D45: 172.82 | E45: 156.95 | F45: 240.82 | G45: 331.87 | H45: 318.51 | I45: 542.81
B46: PE | D46: =D45/D43 -> 31.447625 | E46: =E45/E43 -> 24.593182 | F46: =F45/F43 -> 28.616675 | G46: =G45/G43 -> 32.87656 | H46: =H45/H43 -> 29.08839 | I46: =I45/I43 -> 44.356266
B48: Effective Tax Rate | D48: =-D33/D34 -> 0.34190372 | E48: =-E33/E34 -> 0.17501082 | F48: =-F33/F34 -> 0.17943614 | G48: =-G33/G34 -> 0.19344601 | H48: =-H33/H34 -> 0.19786373 | I48: =H48+((0.25-$H$48)/10) -> 0.20307736 | J48: =I48+((0.25-$H$48)/10) -> 0.20829098 | K48: =J48+((0.25-$H$48)/10) -> 0.21350461 | L48: =K48+((0.25-$H$48)/10) -> 0.21871824 | M48: =L48+((0.25-$H$48)/10) -> 0.22393187 | N48: =M48+((0.25-$H$48)/10) -> 0.22914549 | O48: =N48+((0.25-$H$48)/10) -> 0.23435912 | P48: =O48+((0.25-$H$48)/10) -> 0.23957275 | ... R48: =Q48+((0.25-$H$48)/10) -> 0.25
B50: R&D Expense as % of Revenue | D50: =-D12/D6 -> 0.031383738 | E50: =-E12/E6 -> 0.032045104 | F50: =-F12/F6 -> 0.032505604 | G50: =-G12/G6 -> 0.031915749 | H50: =-H12/H6 -> 0.029036724 | I50: =AVERAGE(D50:H50) -> 0.031377384 | J50: =AVERAGE(E50:I50) -> 0.031376113 | K50: =AVERAGE(F50:J50) -> 0.031242315 | L50: =AVERAGE(G50:K50) -> 0.030989657 | M50: =AVERAGE(H50:L50) -> 0.030804438 | N50: =AVERAGE(I50:M50) -> 0.031157981 | O50: =AVERAGE(J50:N50) -> 0.031114101 | P50: =AVERAGE(K50:O50) -> 0.031061699 | ... R50: =AVERAGE(M50:Q50) -> 0.031032759
B51: Interest Expense as % of Revenue | D51: =-D30/D6 -> 0.0073364581 | E51: =-E30/E6 -> 0.0069390902 | F51: =-F30/F6 -> 0.0065097431 | G51: =-G30/G6 -> 0.0052255004 | H51: =-H30/H6 -> 0.008780239 | I51: =AVERAGE($D$51:$H$51) -> 0.0069582062 | J51: =AVERAGE($D$51:$H$51) -> 0.0069582062 | K51: =AVERAGE($D$51:$H$51) -> 0.0069582062 | L51: =AVERAGE($D$51:$H$51) -> 0.0069582062 | M51: =AVERAGE($D$51:$H$51) -> 0.0069582062 | N51: =AVERAGE($D$51:$H$51) -> 0.0069582062 | O51: =AVERAGE($D$51:$H$51) -> 0.0069582062 | P51: =AVERAGE($D$51:$H$51) -> 0.0069582062 | ... R51: =AVERAGE($D$51:$H$51) -> 0.0069582062
B52: Revenue Growth | E52: =E6/D6-1 -> 0.057265131 | F52: =F6/E6-1 -> 0.11777178 | G52: =G6/F6-1 -> 0.072512502 | H52: =H6/G6-1 -> 0.10330412 | I52: =AVERAGE(E52:H52) -> 0.087713385 | J52: =AVERAGE(F52:I52) -> 0.095325448 | K52: =AVERAGE(G52:J52) -> 0.089713865 | L52: =AVERAGE(H52:K52) -> 0.094014205 | M52: =AVERAGE(I52:L52) -> 0.091691726 | N52: =AVERAGE(J52:M52) -> 0.092686311 | O52: =AVERAGE(K52:N52) -> 0.092026527 | P52: =AVERAGE(L52:O52) -> 0.092604692 | ... R52: =AVERAGE(N52:Q52) -> 0.092392461
B53: Dividend Payout Ratio | D53: 0.569 | E53: 0.528 | F53: 0.429 | G53: 0.395 | H53: 0.398 | I53: 0.4 | J53: 0.4 | K53: 0.4 | L53: 0.4 | M53: 0.4 | N53: 0.4 | O53: 0.4 | P53: 0.4 | Q53: 0.4 | R53: 0.4
B54: ROE | D54: 0.137 | E54: 0.147 | F54: 0.178 | G54: 0.202 | H54: 0.215 | I54: 0.2 | J54: 0.2 | K54: 0.2 | L54: 0.2 | M54: 0.2 | N54: 0.2 | O54: 0.2 | P54: 0.2 | Q54: 0.2 | R54: 0.2
B55: Sustainable Growth Rate | E55: =E54*(1-E53) -> 0.069384 | F55: =F54*(1-F53) -> 0.101638 | G55: =G54*(1-G53) -> 0.12221 | H55: =H54*(1-H53) -> 0.12943 | I55: =I54*(1-I53) -> 0.12 | J55: =J54*(1-J53) -> 0.12 | K55: =K54*(1-K53) -> 0.12 | L55: =L54*(1-L53) -> 0.12 | ... R55: =R54*(1-R53) -> 0.12
...

Sheet R&D_Cap
A2: R&D Capitalization Worksheet
A4: Year | B4: t | C4: Expense | D4: Revenue | E4: R&D as %Sales | F4: Amortized R&D
A5: 2011 | B5: -14 | C5: 417 | D5: 16049 | E5: =C5/D5 -> 0.025982927
A6: =A5+1 -> 2012 | B6: =B5+1 -> -13 | C6: 439 | D6: 16311 | E6: =C6/D6 -> 0.026914352
A7: =A6+1 -> 2013 | B7: =B6+1 -> -12 | C7: 644 | D7: 22046 | E7: =C7/D7 -> 0.029211648
A8: =A7+1 -> 2014 | B8: =B7+1 -> -11 | C8: 647 | D8: 22552 | E8: =C8/D8 -> 0.028689252
A9: =A8+1 -> 2015 | B9: =B8+1 -> -10 | C9: 625 | D9: 20855 | E9: =C9/D9 -> 0.029968832
A10: =A9+1 -> 2016 | B10: =B9+1 -> -9 | C10: 587 | D10: 19747 | E10: =C10/D10 -> 0.029726034
A11: =A10+1 -> 2017 | B11: =B10+1 -> -8 | C11: 584 | D11: 20404 | E11: =C11/D11 -> 0.028621839
A12: =A11+1 -> 2018 | B12: =B11+1 -> -7 | C12: 584 | D12: 21609 | E12: =C12/D12 -> 0.027025776
A13: =A12+1 -> 2019 | B13: =B12+1 -> -6 | C13: 606 | D13: 21390 | E13: =C13/D13 -> 0.028330996
A14: =A13+1 -> 2020 | B14: =B13+1 -> -5 | C14: 551 | D14: 17858 | E14: =C14/D14 -> 0.030854519
A15: =A14+1 -> 2021 | B15: =B14+1 -> -4 | C15: 616 | D15: 19628 | E15: =C15/D15 -> 0.031383738 | F15: =0.1*SUM(C5:C14) -> 568.4
A16: =A15+1 -> 2022 | B16: =B15+1 -> -3 | C16: 665 | D16: 20752 | E16: =C16/D16 -> 0.032045104 | F16: =0.1*SUM(C6:C15) -> 588.3
A17: =A16+1 -> 2023 | B17: =B16+1 -> -2 | C17: 754 | D17: 23196 | E17: =C17/D17 -> 0.032505604 | F17: =0.1*SUM(C7:C16) -> 610.9
A18: =A17+1 -> 2024 | B18: =B17+1 -> -1 | C18: 794 | D18: 24878 | E18: =C18/D18 -> 0.031915749 | F18: =0.1*SUM(C8:C17) -> 621.9
A19: =A18+1 -> 2025 | B19: =B18+1 -> 0 | C19: 797 | D19: 27448 | E19: =C19/D19 -> 0.029036724 | F19: =0.1*SUM(C9:C18) -> 636.6
A20: =A19+1 -> 2026 | B20: =B19+1 -> 1 | C20: =D20*E20 -> 891.76723 | D20: ='Inputs FS'!I6 -> 30249.01 | E20: =AVERAGE(E5:E19) -> 0.029480873 | F20: =0.1*SUM(C10:C19) -> 653.8
A21: =A20+1 -> 2027 | B21: =B20+1 -> 2 | C21: =D21*E21 -> 990.54399 | D21: ='Inputs FS'!J6 -> 33335.858 | E21: =AVERAGE(E6:E20) -> 0.029714069 | F21: =0.1*SUM(C11:C20) -> 684.27672
A22: =A21+1 -> 2028 | B22: =B21+1 -> 3 | C22: =D22*E22 -> 1098.4839 | D22: ='Inputs FS'!K6 -> 36737.712 | E22: =AVERAGE(E7:E21) -> 0.029900717 | F22: =0.1*SUM(C12:C21) -> 724.93112
A23: =A22+1 -> 2029 | B23: =B22+1 -> 4 | C23: =D23*E23 -> 1212.4418 | D23: ='Inputs FS'!L6 -> 40486.717 | E23: =AVERAGE(E8:E22) -> 0.029946655 | F23: =0.1*SUM(C13:C22) -> 776.37952
A24: =A23+1 -> 2030 | B24: =B23+1 -> 5 | C24: =D24*E24 -> 1339.9091 | D24: ='Inputs FS'!M$6 -> 44618.301 | E24: =AVERAGE(E9:E23) -> 0.030030482 | F24: =0.1*SUM(C14:C23) -> 837.02369
A25: =A24+1 -> 2031 | B25: =B24+1 -> 6 | C25: =D25*E25 -> 1468.7321 | D25: ='Inputs FS'!N$6 -> 48901.35 | E25: =AVERAGE(E10:E24) -> 0.030034592 | F25: =0.1*SUM(C15:C24) -> 915.9146
A26: =A25+1 -> 2032 | B26: =B25+1 -> 7 | C26: =D26*E26 -> 1601.9238 | D26: ='Inputs FS'!O$6 -> 53299.455 | E26: =AVERAGE(E11:E25) -> 0.030055162 | F26: =0.1*SUM(C16:C25) -> 1001.1878
A27: =A26+1 -> 2033 | B27: =B26+1 -> 8 | C27: =D27*E27 -> 1741.819 | D27: ='Inputs FS'!P$6 -> 57770.401 | E27: =AVERAGE(E12:E26) -> 0.030150717 | F27: =0.1*SUM(C17:C26) -> 1094.8802
A28: =A27+1 -> 2034 | B28: =B27+1 -> 9 | C28: =D28*E28 -> 1890.3546 | D28: ='Inputs FS'!Q$6 -> 62266.598 | E28: =AVERAGE(E13:E27) -> 0.030359047 | F28: =0.1*SUM(C18:C27) -> 1193.6621
A29: =A28+1 -> 2035 | B29: =B28+1 -> 10 | C29: =D29*E29 -> 1977.5723 | D29: ='Inputs FS'!R$6 -> 64850.661 | E29: =AVERAGE(E14:E28) -> 0.03049425 | F29: =0.1*SUM(C19:C28) -> 1303.2975

Sheet WACC
B2: Weighted Average Cost of Capital
B4: US 10yr Govt. Yield | E4: 0.044929 | G4: Capital Structure | N4: Bonds | U4: Synthetic Credit Rating Matrix
B5: Swiss CDS (bps) | E5: 0.000956 | G5: Market Cap | I5: 166064 | J5: =I5/$I$7 -> 0.94512946 | U5: (Range of Interest Coverage Ratio)
B6: US CDS (bps) | E6: 0.004389 | G6: Mkt Value Debt | I6: =R21+S30+P42 -> 9641.0294 | J6: =I6/$I$7 -> 0.054870537 | N6: Maturity | O6: O/S Amt. (mn.) | P6: YTM | Q6: Price | R6: Mkt. Value (mn.)
B7: US DS net of Swiss | E7: =E6-E5 -> 0.003433 | G7: Total | I7: =SUM(I5:I6) -> 175705.03 | J7: =SUM(J5:J6) -> 1 | N7: 2026 | O7: 72 | P7: 0.06218 | Q7: 100 | R7: =O7*(Q7/100) -> 72 | U7: > | V7: ≤ to | W7: Rating is | X7: Spread is
B8: Risk Free Rate | E8: =E4-E7 -> 0.041496 | N8: 2027 | O8: 700 | P8: 0.04263 | Q8: 98.53 | R8: =O8*(Q8/100) -> 689.71 | U8: -100000 | V8: 0.199999 | W8: D2/D | X8: 0.19
N9: 2028 | O9: 500 | P9: 0.04411 | Q9: 99.88 | R9: =O9*(Q9/100) -> 499.4 | U9: 0.2 | V9: 0.649999 | W9: C2/C | X9: 0.16
B10: Cost of Equtiy | G10: Cost of Debt | N10: 2029 | O10: 200 | P10: 0.04685 | Q10: 109.42 | R10: =O10*(Q10/100) -> 218.84 | U10: 0.65 | V10: 0.799999 | W10: Ca2/CC | X10: 0.1261
G11: S&P Long-Term issuer rating | K11: A- | N11: 2030 | O11: 500 | P11: 0.0474 | Q11: 98.96 | R11: =O11*(Q11/100) -> 494.8 | U11: 0.8 | V11: 1.249999 | W11: Caa/CCC | X11: 0.0885
B12: Risk Free Rate | E12: =E8 -> 0.041496 | N12: 2032 | O12: 700 | P12: 0.04817 | Q12: 95.51 | R12: =O12*(Q12/100) -> 668.57 | U12: 1.25 | V12: 1.499999 | W12: B3/B- | X12: 0.0509
B13: Beta | E13: =I56 -> 1.4567442 | G13: Avg. Corporate Default Spread (bps) | K13: 0.0095 | N13: 2033 | O13: 1300 | P13: 0.04858 | Q13: 95.93 | R13: =O13*(Q13/100) -> 1247.09 | U13: 1.5 | V13: 1.749999 | W13: B2/B | X13: 0.0321
B14: Weighted ERP | E14: =R53 -> 0.049454744 | G14: YTM for on-the-run 10 year Bond | K14: 0.05224 | N14: 2034 | O14: 140 | P14: 0.05413 | Q14: 100.24 | R14: =O14*(Q14/100) -> 140.336 | U14: 1.75 | V14: 1.999999 | W14: B1/B+ | X14: 0.0275
B15: CRP | E15: =T53 -> 0.0061547435 | N15: 2035 | O15: 581.5 | P15: 0.03843 | Q15: 98.37 | R15: =O15*(Q15/100) -> 572.02155 | U15: 2 | V15: 2.2499999 | W15: Ba2/BB | X15: 0.0184
B16: Cost of Equity | E16: =E12+E13*E14+E15 -> 0.11969365 | G16: Kd using Default Spread | K16: =E8+K13 -> 0.050996 | N16: 2035 | O16: 27 | P16: 0.0556 | Q16: 97.81 | R16: =O16*(Q16/100) -> 26.4087 | U16: 2.25 | V16: 2.49999 | W16: Ba1/BB+ | X16: 0.0138
G17: Pre-Tax Average Kd | K17: =AVERAGE(K16,K14) -> 0.051618 | N17: 2037 | O17: 240 | P17: 0.05465 | Q17: 102.7 | R17: =O17*(Q17/100) -> 246.48 | U17: 2.5 | V17: 2.999999 | W17: Baa2/BBB | X17: 0.0111
B18: WACC | G18: Post-Tax Average Kd | K18: =K17*(1-I22) -> 0.0387135 | N18: 2042 | O18: 1000 | P18: 0.05623 | Q18: 84.33 | R18: =O18*(Q18/100) -> 843.3 | U18: 3 | V18: 4.249999 | W18: A3/A- | X18: 0.0089
N19: 2047 | O19: 300 | P19: 0.05756 | Q19: 77.55 | R19: =O19*(Q19/100) -> 232.65 | U19: 4.25 | V19: 5.499999 | W19: A2/A | X19: 0.0078
D20: Cost | E20: Weight | G20: Beta Calculation | N20: 2052 | O20: 700 | P20: 0.05701 | Q20: 86.45 | R20: =O20*(Q20/100) -> 605.15 | U20: 5.5 | V20: 6.499999 | W20: A1/A+ | X20: 0.007
B21: Equity Capital | D21: =E16 -> 0.11969365 | E21: =J5 -> 0.94512946 | N21: Total Market Value of Bonds | R21: =SUM(R7:R20) -> 6556.7562 | U21: 6.5 | V21: 8.499999 | W21: Aa2/AA | X21: 0.0055
B22: Debt Capital | D22: =K18 -> 0.0387135 | E22: =J6 -> 0.054870537 | G22: Marginal Tax Rate | I22: 0.25 | U22: 8.5 | V22: 100000 | W22: Aaa/AAA | X22: 0.004
B23: WACC | E23: =SUMPRODUCT(D21:D22,E21:E22) -> 0.11525023 | N23: Un-registered Bond
G24: Co Name | H24: BV Debt | I24: BV Equity | J24: D/E | K24: Reg. Beta | L24: Unlevered Beta
G25: Aerospace Segment | N25: Time to Maturity | O25: O/S Amt. (mn.) | P25: YTM | Q25: Coupon | R25: Price as % | S25: Mkt. Value (mn.)
G26: General Electric | H26: 21320 | I26: 18300 | J26: =H26/I26 -> 1.1650273 | K26: 1.12 | L26: =K26/(1+J26*(1-$I$22)) -> 0.59772528 | N26: 0.58 | O26: 1057 | P26: 0.026 | Q26: 0.00128 | R26: =PV(P26,N26,Q26*1000,-1000)/10 -> 98.449549 | S26: =O26*(R26/100) -> 1040.6117
G27: Boeing Co. | H27: 47210 | I27: 5990 | J27: =H27/I27 -> 7.8814691 | K27: 1.16 | L27: =K27/(1+J27*(1-$I$22)) -> 0.16784588 | N27: 4 | O27: 704 | P27: 0.03287 | Q27: 0.00577 | R27: =PV(P27,N27,Q27*1000,-1000)/10 -> 85.735163 | S27: =O27*(R27/100) -> 603.57555
G28: Airbus | H28: 16820 | I28: 5520 | J28: =H28/I28 -> 3.0471014 | K28: 1.01 | L28: =K28/(1+J28*(1-$I$22)) -> 0.30742763 | N28: 5 | O28: 587 | P28: 0.037 | Q28: 0.0301 | R28: =PV(P28,N28,Q28*1000,-1000)/10 -> 69.87484 | S28: =O28*(R28/100) -> 410.16531
G29: Rolls-Royce | H29: 6250 | I29: 5050 | J29: =H29/I29 -> 1.2376238 | K29: 1.24 | L29: =K29/(1+J29*(1-$I$22)) -> 0.64308087 | N29: 10 | O29: 587 | P29: 0.039 | Q29: 0.03802 | R29: =PV(P29,N29,Q29*1000,-1000)/10 -> 37.217732 | S29: =O29*(R29/100) -> 218.46809
G30: Average Aerospace Peers Unlevered Beta | L30: =AVERAGE(L26:L29) -> 0.42901992 | N30: Total Market Value of Bonds | S30: =SUM(S26:S29) -> 2272.8207
G31: Electrical Segment
G32: GE Vernova | H32: 3910 | I32: 15070 | J32: =H32/I32 -> 0.25945587 | K32: 1.2 | L32: =K32/(1+J32*(1-$I$22)) -> 1.0045271 | N32: Lease Liability
G33: ABB Ltd | H33: 9000 | I33: 15370 | J33: =H33/I33 -> 0.58555628 | K33: 1.08 | L33: =K33/(1+J33*(1-$I$22)) -> 0.750434
G34: Schneider Electric | H34: 20820 | I34: 28700 | J34: =H34/I34 -> 0.72543554 | K34: 1.16 | L34: =K34/(1+J34*(1-$I$22)) -> 0.75125804 | N34: Year | O34: Amount | P34: PV | R34: Terminal Amount | S34: 332
G35: Siemens Energy | H35: 5820 | I35: 12830 | J35: =H35/I35 -> 0.45362432 | K35: 1.36 | L35: =K35/(1+J35*(1-$I$22)) -> 1.0147601 | N35: 1 | O35: 191 | P35: =O35/(1+$K$17)^N35 -> 181.62489 | R35: Years Implied | S35: =S34/AVERAGE(O35:O39) -> 2.5577812
G36: Average Electrical Peers Unlevered Beta | L36: =AVERAGE(L32:L35) -> 0.88024482 | N36: =N35+1 -> 2 | O36: 157 | P36: =O36/(1+$K$17)^N36 -> 141.96577
G37: Mobility Segment | N37: =N36+1 -> 3 | O37: 126 | P37: =O37/(1+$K$17)^N37 -> 108.34192
G38: Cummins Inc | H38: 8240 | I38: 13370 | J38: =H38/I38 -> 0.61630516 | K38: 1 | L38: =K38/(1+J38*(1-$I$22)) -> 0.68388747 | N38: =N37+1 -> 4 | O38: 100 | P38: =O38/(1+$K$17)^N38 -> 81.765097
G39: Volvo | H39: 27120 | I39: 20080 | J39: =H39/I39 -> 1.3505976 | K39: 1.1 | L39: =K39/(1+J39*(1-$I$22)) -> 0.54646215 | N39: =N38+1 -> 5 | O39: 75 | P39: =O39/(1+$K$17)^N39 -> 58.313782
G40: Paccar Inc | H40: 14950 | I40: 19760 | J40: =H40/I40 -> 0.75657895 | K40: 0.88 | L40: =K40/(1+J40*(1-$I$22)) -> 0.56142707 | N40: =N39+1 -> 6 | O40: =$S$34/2 -> 166 | P40: =O40/(1+$K$17)^N40 -> 122.73262
G41: HD Hyundai | H41: 423.64 | I41: 6410 | J41: =H41/I41 -> 0.066090484 | K41: 0.72 | L41: =K41/(1+J41*(1-$I$22)) -> 0.68599661 | N41: =N40+1 -> 7 | O41: =$S$34/2 -> 166 | P41: =O41/(1+$K$17)^N41 -> 116.70837
G42: Average Mobility Peers Unlevered Beta | L42: =AVERAGE(L38:L41) -> 0.61944333 | N42: Total Lease Liabiltiy | P42: =SUM(P35:P41) -> 811.45244
...

Sheet DCF
B2: FYE ending December 31 | D2: 2025 | E2: =D2+1 -> 2026 | F2: =E2+1 -> 2027 | G2: =F2+1 -> 2028 | H2: =G2+1 -> 2029 | I2: =H2+1 -> 2030 | J2: =I2+1 -> 2031 | K2: =J2+1 -> 2032 | L2: =K2+1 -> 2033 | ... N2: =M2+1 -> 2035
B4: Discounted Cash Flow
B6: Normalized EBIT | D6: ='Inputs FS'!H40 -> 5401.1373 | E6: ='Inputs FS'!I40 -> 6071.3582 | F6: ='Inputs FS'!J40 -> 6824.746 | G6: ='Inputs FS'!K40 -> 7671.6209 | H6: ='Inputs FS'!L40 -> 8623.5834 | I6: ='Inputs FS'!M40 -> 9693.6739 | J6: ='Inputs FS'!N40 -> 10836.684 | K6: ='Inputs FS'!O40 -> 12047.543 | ... N6: ='Inputs FS'!R40 -> 15555.739
B7: NOPAT | D7: =D6*(1-'Inputs FS'!H48) -> 4332.4482 | E7: =E6*(1-'Inputs FS'!I48) -> 4838.4028 | F7: =F6*(1-'Inputs FS'!J48) -> 5403.213 | G7: =G6*(1-'Inputs FS'!K48) -> 6033.6944 | H7: =H6*(1-'Inputs FS'!L48) -> 6737.4485 | I7: =I6*(1-'Inputs FS'!M48) -> 7522.9514 | J7: =J6*(1-'Inputs FS'!N48) -> 8353.5065 | K7: =K6*(1-'Inputs FS'!O48) -> 9224.0914 | ... N7: =N6*(1-'Inputs FS'!R48) -> 11666.804
B8: add: Depreciation & Amortization | D8: =-'Inputs FS'!H23 -> 1006 | E8: =-'Inputs FS'!I23 -> 1249.5119 | F8: =-'Inputs FS'!J23 -> 1339.2445 | G8: =-'Inputs FS'!K23 -> 1433.3165 | H8: =-'Inputs FS'!L23 -> 1572.2487 | I8: =-'Inputs FS'!M23 -> 1748.8722 | J8: =-'Inputs FS'!N23 -> 1941.6444 | K8: =-'Inputs FS'!O23 -> 2099.1934 | ... N8: =-'Inputs FS'!R23 -> 2552.3014
B9: less: Capex | D9: =-'Inputs FS'!H164 -> -2409 | E9: =-'Inputs FS'!I164 -> -1611.5195 | F9: =-'Inputs FS'!J164 -> -1775.9716 | G9: =-'Inputs FS'!K164 -> -1957.2058 | H9: =-'Inputs FS'!L164 -> -2156.9345 | I9: =-'Inputs FS'!M164 -> -2377.0451 | J9: =-'Inputs FS'!N164 -> -2605.225 | K9: =-'Inputs FS'!O164 -> -2839.5345 | ... N9: =-'Inputs FS'!R164 -> -3454.9264
B10: less: Change in NWC | D10: ='Inputs FS'!H194 -> -1366 | E10: ='Inputs FS'!I194 -> 211.19247 | F10: ='Inputs FS'!J194 -> -668.02865 | G10: ='Inputs FS'!K194 -> -736.39138 | H10: ='Inputs FS'!L194 -> -811.74996 | I10: ='Inputs FS'!M194 -> -894.82029 | J10: ='Inputs FS'!N194 -> -928.01543 | K10: ='Inputs FS'!O194 -> -953.36668 | ... N10: ='Inputs FS'!R194 -> -562.46941
B11: Free Cash Flow to Firm | D11: =SUM(D6:D10) -> 6964.5855 | E11: =SUM(E6:E10) -> 10758.946 | F11: =SUM(F6:F10) -> 11123.203 | G11: =SUM(G6:G10) -> 12445.035 | H11: =SUM(H6:H10) -> 13964.596 | I11: =SUM(I6:I10) -> 15693.632 | J11: =SUM(J6:J10) -> 17598.594 | K11: =SUM(K6:K10) -> 19577.927 | ... N11: =SUM(N6:N10) -> 25757.449
B13: WACC | D13: =WACC!E23 -> 0.11525023
B14: Terminal Growth Rate | D14: =WACC!E8 -> 0.041496
B16: Terminal Value | D16: =N11*(1+D14)/(D13-D14) -> 363725.3
B17: PV of Terminal Value | D17: =D16*N23 -> 129043.6
B19: Valuation Date | D19: =TODAY() -> 46204
B20: Fiscal Year End Date | D20: 46387
B22: Year Frac | E22: =YEARFRAC($D$19,$D$20) -> 0.5 | F22: =E22+1 -> 1.5 | G22: =F22+1 -> 2.5 | H22: =G22+1 -> 3.5 | I22: =H22+1 -> 4.5 | J22: =I22+1 -> 5.5 | K22: =J22+1 -> 6.5 | L22: =K22+1 -> 7.5 | M22: =L22+1 -> 8.5 | N22: =M22+1 -> 9.5
B23: Present Value Factor | E23: =1/(1+$D$13)^DCF!E22 -> 0.9469212 | F23: =1/(1+$D$13)^DCF!F22 -> 0.84906613 | G23: =1/(1+$D$13)^DCF!G22 -> 0.76132343 | H23: =1/(1+$D$13)^DCF!H22 -> 0.68264808 | I23: =1/(1+$D$13)^DCF!I22 -> 0.61210306 | J23: =1/(1+$D$13)^DCF!J22 -> 0.54884818 | K23: =1/(1+$D$13)^DCF!K22 -> 0.49213008 | L23: =1/(1+$D$13)^DCF!L22 -> 0.44127324 | ... N23: =1/(1+$D$13)^DCF!N22 -> 0.35478312
B25: PV of FCFF | E25: =E11*E23 -> 10187.874 | F25: =F11*F23 -> 9444.3351 | G25: =G11*G23 -> 9474.6965 | H25: =H11*H23 -> 9532.9048 | I25: =I11*I23 -> 9606.1204 | J25: =J11*J23 -> 9658.9564 | K25: =K11*K23 -> 9634.8866 | L25: =L11*L23 -> 9560.8363 | ... N25: =N11*N23 -> 9138.3079
B27: Enterprise Value | E27: =SUM(E25:N25)+D17 -> 224720.87
B28: less: Debt | E28: =-('Inputs FS'!H102+'Inputs FS'!H105+'Inputs FS'!H111+'Inputs FS'!H114) -> -10532
B29: add: Cash & Equivalents | E29: ='Inputs FS'!H84 -> 803
B30: Equity Value | E30: =SUM(E27:E29) -> 214991.87
B31: Total Shares Outstanding | E31: =D45 -> 390.20107
B32: Implied per Share Price | E32: =E30/E31 -> 550.97716
B33: Current Market Price | E33: 427.43
B35: Upside Potential | E35: =E32/E33-1 -> 0.28904652
B37: Total Shares Outstanding Calculation | F37: Tresuary Stock Method
B39: Common Shares O/S | D39: 388.3 | F39: Stock Options | I39: 1.6
B40: Preferred Shares | D40: 0.01 | F40: Weighted Avg. Exercise Price | I40: 119.93
B41: Deferred Common O/S | D41: 0.04 | F41: Current Market Price | I41: =E33 -> 427.43
B42: RSUs/RSAs | D42: 0.6 | F42: Amount Received from Exercise | I42: =I39*I40 -> 191.888
B43: PSUs | D43: 0.1 | F43: Shares Repurchased | I43: =-I42/I41 -> -0.44893433
B44: Net Stock Options Issued | D44: =I44 -> 1.1510657 | F44: Number of Share Issued | I44: =I39+I43 -> 1.1510657
B45: Total Shares | D45: =SUM(D39:D44) -> 390.20107
B48: Sensitivity Analysis
E50: WACC
D51: Terminal Growth Rate | E51: =E32 -> 550.97716 | F51: =G51-0.5% -> 0.10510711 | G51: =H51-0.5% -> 0.11010711 | H51: 0.11510711 | I51: =H51+0.5% -> 0.12010711 | J51: =I51+0.5% -> 0.12510711
E52: =E53-0.5% -> 0.030911 | F52: 586.61526 | G52: 544.50996 | H52: 507.52448 | I52: 474.79367 | J52: 445.63624
E53: =E54-0.5% -> 0.035911 | F53: 614.10588 | G53: 567.62517 | H53: 527.13087 | I53: 491.55237 | J53: 460.05931
E54: 0.040911 | F54: 645.87878 | G54: 594.08093 | H54: 549.37976 | I54: 510.42717 | J54: 476.19541
E55: =E54+0.5% -> 0.045911 | F55: 683.01908 | G55: 624.65776 | H55: 574.844 | I55: 531.84587 | J55: 494.369
...

Sheet RV
B2: Trading Comparables Multiples Method
B4: Comparable Peers | D4: Market Data | J4: Financial Data (LTM) | P4: Trading Multiples
D5: Ticker | E5: CMP | F5: Shares O/S | G5: Market Cap. | H5: Enterprise Value | J5: Revenue | K5: EBITDA | L5: EBIT | M5: EPS | N5: BVPS | P5: EV/Sales | Q5: EV/EBITDA | R5: EV/EBIT | S5: PE | T5: PB | U5: PS
B7: Eaton Corp | D7: ETN | E7: 420.2 | F7: 388.3 | G7: 163155.9 | H7: 184281.9 | J7: 28522 | K7: 6758 | L7: 5712 | M7: 11.21 | N7: 50.79 | P7: =H7/J7 -> 6.4610441 | Q7: =IF(K7>0,H7/K7,0) -> 27.268704 | R7: =IF(L7>0,H7/L7,0) -> 32.262237 | S7: =IF(M7>0,E7/M7,0) -> 37.484389 | T7: =E7/N7 -> 8.2732821 | U7: =E7/(J7/F7) -> 5.7206248
B9: Aerospace Segment
B10: General Electric | D10: GE | E10: 326.1 | F10: 1043.3 | G10: 340310 | H10: 388038.5 | J10: 48313 | K10: 9931 | L10: 8335 | M10: 6.86 | N10: 17.31 | P10: =H10/J10 -> 8.0317616 | Q10: =IF(K10>0,H10/K10,0) -> 39.073457 | R10: =IF(L10>0,H10/L10,0) -> 46.555309 | S10: =IF(M10>0,E10/M10,0) -> 47.536443 | T10: =E10/N10 -> 18.838821 | U10: =E10/(J10/F10) -> 7.0419997
B11: Howmet Aerospace | D11: HWM | E11: 251.9 | F11: 400.1 | G11: 100787.1 | H11: 103200.1 | J11: 8623 | K11: 2677 | L11: 2314 | M11: 4.15 | N11: 13.77 | P11: =H11/J11 -> 11.968004 | Q11: =IF(K11>0,H11/K11,0) -> 38.550654 | R11: =IF(L11>0,H11/L11,0) -> 44.598142 | S11: =IF(M11>0,E11/M11,0) -> 60.698795 | T11: =E11/N11 -> 18.293391 | U11: =E11/(J11/F11) -> 11.68795
B12: Airbus | D12: AIR FP | E12: 205.69 | F12: 792.3 | G12: 162672 | H12: 147288 | J12: 162994.2 | K12: 9399.8 | L12: 5698.8 | M12: 7.68 | N12: 38.51 | P12: =H12/J12 -> 0.90363952 | Q12: =IF(K12>0,H12/K12,0) -> 15.66927 | R12: =IF(L12>0,H12/L12,0) -> 25.845441 | S12: =IF(M12>0,E12/M12,0) -> 26.782552 | T12: =E12/N12 -> 5.3412101 | U12: =E12/(J12/F12) -> 0.99984041
B13: Rolls-Royce | D13: RR/LN | E13: 16.92688 | F13: 8365.1 | G13: 141631.3 | H13: 139025 | J13: 27970.4 | K13: 5722.8 | L13: 4748.2 | M13: 0.93 | N13: 0.43 | P13: =H13/J13 -> 4.970433 | Q13: =IF(K13>0,H13/K13,0) -> 24.293178 | R13: =IF(L13>0,H13/L13,0) -> 29.279516 | S13: =IF(M13>0,E13/M13,0) -> 18.200946 | T13: =E13/N13 -> 39.364837 | U13: =E13/(J13/F13) -> 5.0623174
B14: Median | P14: =MEDIAN(P10:P13) -> 6.5010973 | Q14: =MEDIAN(Q10:Q13) -> 31.421916 | R14: =MEDIAN(R10:R13) -> 36.938829 | S14: =MEDIAN(S10:S13) -> 37.159498 | T14: =MEDIAN(T10:T13) -> 18.566106 | U14: =MEDIAN(U10:U13) -> 6.0521586
B15: Average | P15: =AVERAGE(P10:P13) -> 6.4684596 | Q15: =AVERAGE(Q10:Q13) -> 29.39664 | R15: =AVERAGE(R10:R13) -> 36.569602 | S15: =AVERAGE(S10:S13) -> 38.304684 | T15: =AVERAGE(T10:T13) -> 20.459565 | U15: =AVERAGE(U10:U13) -> 6.1980268
B16: Minimum | P16: =MIN(P10:P13) -> 0.90363952 | Q16: =MIN(Q10:Q13) -> 15.66927 | R16: =MIN(R10:R13) -> 25.845441 | S16: =MIN(S10:S13) -> 18.200946 | T16: =MIN(T10:T13) -> 5.3412101 | U16: =MIN(U10:U13) -> 0.99984041
B17: Maximum | P17: =MAX(P10:P13) -> 11.968004 | Q17: =MAX(Q10:Q13) -> 39.073457 | R17: =MAX(R10:R13) -> 46.555309 | S17: =MAX(S10:S13) -> 60.698795 | T17: =MAX(T10:T13) -> 39.364837 | U17: =MAX(U10:U13) -> 11.68795
B19: Electrical Segment
B20: GE Vernova | D20: GEV | E20: 962.37 | F20: 268.7 | G20: 258608.1 | H20: 253046.6 | J20: 39375 | K20: 2794 | L20: 1736 | M20: 21.27 | N20: 51.81 | P20: =H20/J20 -> 6.4265803 | Q20: =IF(K20>0,H20/K20,0) -> 90.56786 | R20: =IF(L20>0,H20/L20,0) -> 145.76417 | S20: =IF(M20>0,E20/M20,0) -> 45.245416 | T20: =E20/N20 -> 18.574986 | U20: =E20/(J20/F20) -> 6.5673351
B21: ABB Ltd | D21: ABBN SW | E21: 107.52 | F21: 1823.2 | G21: 195650 | H21: 199310 | J21: 35769 | K21: 7254 | L21: 6395 | M21: 2.59 | N21: 5.14 | P21: =H21/J21 -> 5.5721435 | Q21: =IF(K21>0,H21/K21,0) -> 27.475875 | R21: =IF(L21>0,H21/L21,0) -> 31.166536 | S21: =IF(M21>0,E21/M21,0) -> 41.513514 | T21: =E21/N21 -> 20.918288 | U21: =E21/(J21/F21) -> 5.4804569
B22: Schneider Electric | D22: SU FP | E22: 326.95 | F22: 577.1 | G22: 188687.92 | H22: 204191.32 | J22: 46576.32 | K22: 10109.4 | L22: 8193.08 | M22: 8.61 | N22: 48.72 | P22: =H22/J22 -> 4.3840157 | Q22: =IF(K22>0,H22/K22,0) -> 20.198164 | R22: =IF(L22>0,H22/L22,0) -> 24.922413 | S22: =IF(M22>0,E22/M22,0) -> 37.973287 | T22: =E22/N22 -> 6.7107964 | U22: =E22/(J22/F22) -> 4.0510466
B23: Siemens Energy | D23: ENR GY | E23: 184.9968 | F23: 861.1 | G23: 159301.64 | H23: 150371.96 | J23: 46537.5 | K23: 5514.9 | L23: 3714.7 | M23: 1.89 | N23: 14.64 | P23: =H23/J23 -> 3.2311998 | Q23: =IF(K23>0,H23/K23,0) -> 27.266489 | R23: =IF(L23>0,H23/L23,0) -> 40.480243 | S23: =IF(M23>0,E23/M23,0) -> 97.881905 | T23: =E23/N23 -> 12.636393 | U23: =E23/(J23/F23) -> 3.4230619
B24: Median | P24: =MEDIAN(P20:P23) -> 4.9780796 | Q24: =MEDIAN(Q20:Q23) -> 27.371182 | R24: =MEDIAN(R20:R23) -> 35.82339 | S24: =MEDIAN(S20:S23) -> 43.379465 | T24: =MEDIAN(T20:T23) -> 15.605689 | U24: =MEDIAN(U20:U23) -> 4.7657518
B25: Average | P25: =AVERAGE(P20:P23) -> 4.9034848 | Q25: =AVERAGE(Q20:Q23) -> 41.377097 | R25: =AVERAGE(R20:R23) -> 60.583341 | S25: =AVERAGE(S20:S23) -> 55.65353 | T25: =AVERAGE(T20:T23) -> 14.710116 | U25: =AVERAGE(U20:U23) -> 4.8804751
B26: Minimum | P26: =MIN(P20:P23) -> 3.2311998 | Q26: =MIN(Q20:Q23) -> 20.198164 | R26: =MIN(R20:R23) -> 24.922413 | S26: =MIN(S20:S23) -> 37.973287 | T26: =MIN(T20:T23) -> 6.7107964 | U26: =MIN(U20:U23) -> 3.4230619
B27: Maximum | P27: =MAX(P20:P23) -> 6.4265803 | Q27: =MAX(Q20:Q23) -> 90.56786 | R27: =MAX(R20:R23) -> 145.76417 | S27: =MAX(S20:S23) -> 97.881905 | T27: =MAX(T20:T23) -> 20.918288 | U27: =MAX(U20:U23) -> 6.5673351
B29: Mobility Segment
B30: Cummins Inc | D30: CMI | E30: 682.61 | F30: 138 | G30: 94156.8 | H30: 100235.8 | J30: 33894 | K30: 5174 | L30: 4056 | M30: 21.39 | N30: 89.5 | P30: =H30/J30 -> 2.9573317 | Q30: =IF(K30>0,H30/K30,0) -> 19.37298 | R30: =IF(L30>0,H30/L30,0) -> 24.712968 | S30: =IF(M30>0,E30/M30,0) -> 31.912576 | T30: =E30/N30 -> 7.6269274 | U30: =E30/(J30/F30) -> 2.7792583
B31: Volvo | D31: VOLVB SS | E31: 34.784651 | F31: 1592.7 | G31: 70742.329 | H31: 66051.205 | J31: 49660.2 | K31: 7369.1 | L31: 4866.3 | M31: 1.81 | N31: 10.01 | P31: =H31/J31 -> 1.3300632 | Q31: =IF(K31>0,H31/K31,0) -> 8.9632663 | R31: =IF(L31>0,H31/L31,0) -> 13.573188 | S31: =IF(M31>0,E31/M31,0) -> 19.218039 | T31: =E31/N31 -> 3.4749901 | U31: =E31/(J31/F31) -> 1.115612
B32: Paccar Inc | D32: PCAR | E32: 117.555 | F32: 526.3 | G32: 61886 | H32: 53290.6 | J32: 27779.6 | K32: 3150.2 | L32: 2751.2 | M32: 4.7 | N32: 37.54 | P32: =H32/J32 -> 1.9183358 | Q32: =IF(K32>0,H32/K32,0) -> 16.916577 | R32: =IF(L32>0,H32/L32,0) -> 19.369948 | S32: =IF(M32>0,E32/M32,0) -> 25.011702 | T32: =E32/N32 -> 3.1314598 | U32: =E32/(J32/F32) -> 2.227145
B33: HD Hyundai | D33: 005380 KS | E33: 456.93 | F33: 262.2 | G33: 107392.4 | H33: 180093.1 | J33: 122579.5 | K33: 9105.7 | L33: 6755.4 | M33: 10.24 | N33: 60.37 | P33: =H33/J33 -> 1.4691943 | Q33: =IF(K33>0,H33/K33,0) -> 19.778062 | R33: =IF(L33>0,H33/L33,0) -> 26.659132 | S33: =IF(M33>0,E33/M33,0) -> 44.62207 | T33: =E33/N33 -> 7.5688256 | U33: =E33/(J33/F33) -> 0.9773824
B34: Median | P34: =MEDIAN(P30:P33) -> 1.693765 | Q34: =MEDIAN(Q30:Q33) -> 18.144779 | R34: =MEDIAN(R30:R33) -> 22.041458 | S34: =MEDIAN(S30:S33) -> 28.462139 | T34: =MEDIAN(T30:T33) -> 5.5219079 | U34: =MEDIAN(U30:U33) -> 1.6713785
B35: Average | P35: =AVERAGE(P30:P33) -> 1.9187312 | Q35: =AVERAGE(Q30:Q33) -> 16.257721 | R35: =AVERAGE(R30:R33) -> 21.078809 | S35: =AVERAGE(S30:S33) -> 30.191097 | T35: =AVERAGE(T30:T33) -> 5.4505507 | U35: =AVERAGE(U30:U33) -> 1.7748494
B36: Minimum | P36: =MIN(P30:P33) -> 1.3300632 | Q36: =MIN(Q30:Q33) -> 8.9632663 | R36: =MIN(R30:R33) -> 13.573188 | S36: =MIN(S30:S33) -> 19.218039 | T36: =MIN(T30:T33) -> 3.1314598 | U36: =MIN(U30:U33) -> 0.9773824
B37: Maximum | P37: =MAX(P30:P33) -> 2.9573317 | Q37: =MAX(Q30:Q33) -> 19.778062 | R37: =MAX(R30:R33) -> 26.659132 | S37: =MAX(S30:S33) -> 44.62207 | T37: =MAX(T30:T33) -> 7.6269274 | U37: =MAX(U30:U33) -> 2.7792583
B39: Relative Valuation
B41: Total Debt | D41: 21833
B42: Cash & Equivalent | D42: 751
B44: Segment | D44: Weight | E44: Implied Median Share Price | L44: Implied Average Share Price
E45: EV/Sales | F45: EV/EBITDA | G45: EV/EBIT | H45: PE | I45: PB | J45: PS | L45: EV/Sales | M45: EV/EBITDA | N45: EV/EBIT | O45: PE | P45: PB | Q45: PS | S45: Segment | V45: EV/EBITDA | W45: PE
B47: Aerospace | D47: 0.17012468 | E47: =((J$7*P$14)+$D$41-$D$42)/$F$7 -> 531.82152 | F47: =((K$7*Q$14)+$D$41-$D$42)/$F$7 -> 601.16227 | G47: =((L$7*R$14)+$D$41-$D$42)/$F$7 -> 597.67343 | H47: =M$7*S$14 -> 416.55797 | I47: =N$7*T$14 -> 942.97255 | J47: =($J$7*$U$14)/$F$7 -> 444.55232 | L47: =((P$15*J$7)+$D$42-$D$41)/$F$7 -> 420.83802 | M47: =((Q$15*K$7)+$D$42-$D$41)/$F$7 -> 457.32807 | N47: =((R$15*L$7)+$D$42-$D$41)/$F$7 -> 483.65585 | O47: =S$15*M$7 -> 429.39551 | P47: =T$15*N$7 -> 1039.1413 | Q47: =($J$7*U15)/$F$7 -> 455.26686 | S47: Aerospace | U47: 0.17012468 | V47: 31.42 | W47: 37.16
B48: Electrical | D48: 0.80441868 | E48: =((J$7*P$24)+$D$41-$D$42)/$F$7 -> 419.95052 | F48: =((K$7*Q$24)+$D$41-$D$42)/$F$7 -> 530.66302 | G48: =((L$7*R$24)+$D$41-$D$42)/$F$7 -> 581.26501 | H48: =M$7*S$24 -> 486.2838 | I48: =N$7*T$24 -> 792.61297 | J48: =($J$7*U24)/$F$7 -> 350.06122 | L48: =((P$25*J$7)+$D$42-$D$41)/$F$7 -> 305.88513 | M48: =((Q$25*K$7)+$D$42-$D$41)/$F$7 -> 665.83678 | N48: =((R$25*L$7)+$D$42-$D$41)/$F$7 -> 836.90456 | O48: =S$25*M$7 -> 623.87607 | P48: =T$25*N$7 -> 747.12678 | Q48: =($J$7*U25)/$F$7 -> 358.48806 | S48: Electrical | U48: 0.80441868 | V48: 27.37 | W48: 43.38
B49: Mobility | D49: 0.025456642 | E49: =((J$7*P$34)+$D$41-$D$42)/$F$7 -> 178.70607 | F49: =((K$7*Q$34)+$D$41-$D$42)/$F$7 -> 370.08605 | G49: =((L$7*R$34)+$D$41-$D$42)/$F$7 -> 378.52899 | H49: =M$7*S$34 -> 319.06058 | I49: =N$7*T$34 -> 280.4577 | J49: =($J$7*U34)/$F$7 -> 122.76862 | L49: =((P$35*J$7)+$D$42-$D$41)/$F$7 -> 86.644482 | M49: =((Q$35*K$7)+$D$42-$D$41)/$F$7 -> 228.65743 | N49: =((R$35*L$7)+$D$42-$D$41)/$F$7 -> 255.78202 | O49: =S$35*M$7 -> 338.4422 | P49: =T$35*N$7 -> 276.83347 | Q49: =($J$7*U35)/$F$7 -> 130.36893 | S49: Mobility | U49: 0.025456642 | V49: 18.14 | W49: 28.46
B50: Weighted Average | D50: =SUM(D47:D49) -> 1 | E50: =SUMPRODUCT($D$47:$D$49,E47:E49) -> 432.84126 | F50: =SUMPRODUCT($D$47:$D$49,F47:F49) -> 538.56893 | G50: =SUMPRODUCT($D$47:$D$49,G47:G49) -> 578.89551 | H50: =SUMPRODUCT($D$47:$D$49,H47:H49) -> 470.16477 | I50: =SUMPRODUCT($D$47:$D$49,I47:I49) -> 805.15509 | J50: =SUMPRODUCT($D$47:$D$49,J47:J49) -> 360.35038 | L50: =SUMPRODUCT($D$47:$D$49,L47:L49) -> 319.86032 | M50: =SUMPRODUCT($D$47:$D$49,M47:M49) -> 619.23518 | N50: =SUMPRODUCT($D$47:$D$49,N47:N49) -> 762.01481 | O50: =SUMPRODUCT($D$47:$D$49,O47:O49) -> 583.52394 | P50: =SUMPRODUCT($D$47:$D$49,P47:P49) -> 784.83357 | Q50: =SUMPRODUCT($D$47:$D$49,Q47:Q49) -> 369.14537 | S50: Weighted Average | U50: =SUM(U47:U49) -> 1 | V50: =SUMPRODUCT($U$47:$U$49,V47:V49) -> 27.82404 | W50: =SUMPRODUCT($U$47:$U$49,W47:W49) -> 41.942011
...

Sheet Dupont
B2: FYE ending December 31 | D2: 2021 | E2: =D2+1 -> 2022 | F2: =E2+1 -> 2023 | G2: =F2+1 -> 2024 | H2: =G2+1 -> 2025 | I2: =H2+1 -> 2026 | J2: =I2+1 -> 2027 | K2: =J2+1 -> 2028 | L2: =K2+1 -> 2029 | ... R2: =Q2+1 -> 2035
B4: Dupont Analysis
B6: Tax Burden (NI/EBT) | D6: ='Inputs FS'!D34/'Inputs FS'!D31 -> 0.74520995 | E6: ='Inputs FS'!E34/'Inputs FS'!E31 -> 0.851056 | F6: ='Inputs FS'!F34/'Inputs FS'!F31 -> 0.84786277 | G6: ='Inputs FS'!G34/'Inputs FS'!G31 -> 0.83790971 | H6: ='Inputs FS'!H34/'Inputs FS'!H31 -> 0.8348195 | I6: 0.83 | J6: 0.83 | K6: 0.83 | L6: 0.83 | M6: 0.83 | N6: 0.83 | O6: 0.83 | P6: 0.83 | Q6: 0.83 | R6: 0.83
B7: Interest Burden (EBT/EBIT) | D7: ='Inputs FS'!D31/'Inputs FS'!D28 -> 0.95336183 | E7: ='Inputs FS'!E31/'Inputs FS'!E28 -> 0.95401858 | F7: ='Inputs FS'!F31/'Inputs FS'!F28 -> 0.9633593 | G7: ='Inputs FS'!G31/'Inputs FS'!G28 -> 0.97329554 | H7: ='Inputs FS'!H31/'Inputs FS'!H28 -> 0.95480459 | I7: =AVERAGE(D7:H7) -> 0.95976797 | J7: =AVERAGE(E7:I7) -> 0.9610492 | K7: =AVERAGE(F7:J7) -> 0.96245532 | L7: =AVERAGE(G7:K7) -> 0.96227452 | M7: =AVERAGE(H7:L7) -> 0.96007032 | N7: =AVERAGE(I7:M7) -> 0.96112346 | O7: =AVERAGE(J7:N7) -> 0.96139456 | P7: =AVERAGE(K7:O7) -> 0.96146364 | ... R7: =AVERAGE(M7:Q7) -> 0.96106346
B8: EBIT Margin | D8: ='Inputs FS'!D28/'Inputs FS'!D6 -> 0.15730589 | E8: ='Inputs FS'!E28/'Inputs FS'!E6 -> 0.15091076 | F8: ='Inputs FS'!F28/'Inputs FS'!F6 -> 0.17766425 | G8: ='Inputs FS'!G28/'Inputs FS'!G6 -> 0.19567891 | H8: ='Inputs FS'!H28/'Inputs FS'!H6 -> 0.19427281 | I8: =H8+($R$8-$H$8)/10 -> 0.19684553 | J8: =I8+($R$8-$H$8)/10 -> 0.19941825 | K8: =J8+($R$8-$H$8)/10 -> 0.20199096 | L8: =K8+($R$8-$H$8)/10 -> 0.20456368 | M8: =L8+($R$8-$H$8)/10 -> 0.2071364 | N8: =M8+($R$8-$H$8)/10 -> 0.20970912 | O8: =N8+($R$8-$H$8)/10 -> 0.21228184 | P8: =O8+($R$8-$H$8)/10 -> 0.21485456 | Q8: =P8+($R$8-$H$8)/10 -> 0.21742728 | R8: 0.22
B9: Asset Turnover | D9: ='Inputs FS'!D6/'Inputs FS'!D89 -> 0.57683604 | E9: ='Inputs FS'!E6/'Inputs FS'!E89 -> 0.59266029 | F9: ='Inputs FS'!F6/'Inputs FS'!F89 -> 0.60355953 | G9: ='Inputs FS'!G6/'Inputs FS'!G89 -> 0.6481853 | H9: ='Inputs FS'!H6/'Inputs FS'!H89 -> 0.66538993 | I9: =AVERAGE($D$9:$H$9) -> 0.61732622 | J9: =AVERAGE($D$9:$H$9) -> 0.61732622 | K9: =AVERAGE($D$9:$H$9) -> 0.61732622 | L9: =AVERAGE($D$9:$H$9) -> 0.61732622 | M9: =AVERAGE($D$9:$H$9) -> 0.61732622 | N9: =AVERAGE($D$9:$H$9) -> 0.61732622 | O9: =AVERAGE($D$9:$H$9) -> 0.61732622 | P9: =AVERAGE($D$9:$H$9) -> 0.61732622 | ... R9: =AVERAGE($D$9:$H$9) -> 0.61732622
B10: Financial Leverage | D10: ='Inputs FS'!D89/'Inputs FS'!D99 -> 2.0683849 | E10: ='Inputs FS'!E89/'Inputs FS'!E99 -> 2.0506589 | F10: ='Inputs FS'!F89/'Inputs FS'!F99 -> 2.0154177 | G10: ='Inputs FS'!G89/'Inputs FS'!G99 -> 2.071178 | H10: ='Inputs FS'!H89/'Inputs FS'!H99 -> 2.1188043 | I10: =AVERAGE(D10:H10) -> 2.0648887 | J10: =AVERAGE(E10:I10) -> 2.0641895 | K10: =AVERAGE(F10:J10) -> 2.0668956 | L10: =AVERAGE(G10:K10) -> 2.0771912 | M10: =AVERAGE(H10:L10) -> 2.0783939 | N10: =AVERAGE(I10:M10) -> 2.0703118 | O10: =AVERAGE(J10:N10) -> 2.0713964 | P10: =AVERAGE(K10:O10) -> 2.0728378 | ... R10: =AVERAGE(M10:Q10) -> 2.0733932
B11: Return on Equity | D11: =PRODUCT(D6:D10) -> 0.13334144 | E11: =PRODUCT(E6:E10) -> 0.14891362 | F11: =PRODUCT(F6:F10) -> 0.1765221 | G11: =PRODUCT(G6:G10) -> 0.214241 | H11: =PRODUCT(H6:H10) -> 0.2183163 | I11: =PRODUCT(I6:I10) -> 0.19988549 | J11: =PRODUCT(J6:J10) -> 0.2026996 | K11: =PRODUCT(K6:K10) -> 0.20588461 | ... R11: =PRODUCT(R6:R10) -> 0.22462042
