Workbook
Name EV: '[1]Inputs&Assumptions'!$D$13
Name EVEBITDA: '[1]Inputs&Assumptions'!$D$17
Name FYEnd: '[1]Inputs&Assumptions'!$D$6
Name IQ_CH: 110000
Name IQ_CQ: 5000
Name IQ_CY: 10000
Name IQ_DAILY: 500000
Name IQ_FH: 100000
Name IQ_FQ: 500
Name IQ_FY: 1000
Name IQ_LTM: 2000
Name IQ_MONTH: 15000
Name IQ_NTM: 6000
Name IQ_WEEK: 50000
Name IQ_YTD: 3000
Name Rf: '[1]Inputs&Assumptions'!$D$20
Name SharesQty: '[1]Inputs&Assumptions'!$D$10
Name TaxRate: '[1]Inputs&Assumptions'!$D$14
Name TerminalGrowth: '[1]Inputs&Assumptions'!$D$15
Name ValuationDate: '[1]Inputs&Assumptions'!$D$5
Name WACC: '[1]Inputs&Assumptions'!$D$16

Sheet Cover Page

Sheet TOC
B3: Table of Contents
B5: Particulars | D5: Exihibit No.
B7: Excess Return Model | D7: 1
B8: Dividend Discount Model | D8: =D7+1 -> 2
B9: Ratios | D9: =D8+1 -> 3
B10: Dupont Analysis | D10: =D9+1 -> 4
B11: Weighted Average Cost of Capital | D11: =D10+1 -> 5
B12: Sensitivity Analysis | D12: =D11+1 -> 6
B13: Regression Analysis | D13: =D12+1 -> 7

Sheet Residual Income
B2: ="Exihibit "&VLOOKUP('Residual Income'!B3,TOC!$B$7:$D$13,3,FALSE) -> Exihibit 1
B3: Excess Return Model
B4: (In INR bn.)
B6: Assumptions
B7: Average Net Profit Margin (5yr) | C7: 0.25939811 | E7: Return on Equity | I7: =D13/AVERAGE(D21,D23) -> 0.1747227
B8: Current DPR | C8: 0.1522 | E8: Cost of Equity | I8: =WACC!D14 -> 0.13742137
B9: Target DPR | C9: 0.3 | E9: Sustainable Growth Rate | I9: =I7*(1-AVERAGE(C8:C9)) -> 0.1352179
B11: Fiscal Year ending March | D11: 2025 | E11: =D11+1 -> 2026 | F11: =E11+1 -> 2027 | G11: =F11+1 -> 2028 | H11: =G11+1 -> 2029 | I11: =H11+1 -> 2030
B13: Net Income | D13: =$C$7*Regression!O8 -> 483.34029 | E13: =$C$7*Regression!P8 -> 479.09508 | F13: =$C$7*Regression!Q8 -> 528.78979 | G13: =$C$7*Regression!R8 -> 579.8078 | H13: =$C$7*Regression!S8 -> 631.96096 | I13: =$C$7*Regression!T8 -> 685.03883
B14: less: Cost of Equity | D14: =$I$8*D21 -> 351.9966 | E14: =$I$8*E21 -> 408.30856 | F14: =$I$8*F21 -> 462.17977 | G14: =$I$8*G21 -> 519.49079 | H14: =$I$8*H21 -> 579.97594 | I14: =$I$8*I21 -> 643.33454
B15: Excess Return | D15: =D13-D14 -> 131.3437 | E15: =E13-E14 -> 70.786522 | F15: =F13-F14 -> 66.610027 | G15: =G13-G14 -> 60.317009 | H15: =H13-H14 -> 51.985022 | I15: =I13-I14 -> 41.704296
B16: Terminal Value of Excess Return | I16: =(I15*(1+I9))/(I8-I9) -> 21485.847
B18: Dividend Payout Ratio | D18: =C8 -> 0.1522 | E18: =D18+(($C$9-$D$18)/5) -> 0.18176 | F18: =E18+(($C$9-$D$18)/5) -> 0.21132 | G18: =F18+(($C$9-$D$18)/5) -> 0.24088 | H18: =G18+(($C$9-$D$18)/5) -> 0.27044 | I18: =H18+(($C$9-$D$18)/5) -> 0.3
B19: Dividends | D19: =D13*D18 -> 73.564392 | E19: =E13*E18 -> 87.080322 | F19: =F13*F18 -> 111.74386 | G19: =G13*G18 -> 139.6641 | H19: =H13*H18 -> 170.90752 | I19: =I13*I18 -> 205.51165
B21: Beginning Book Value | D21: 2561.44 | E21: =D23 -> 2971.2159 | F21: =E23 -> 3363.2307 | G21: =F23 -> 3780.2766 | H21: =G23 -> 4220.4203 | I21: =H23 -> 4681.4737
B22: add: Retained Earnings | D22: =D13-D19 -> 409.7759 | E22: =E13-E19 -> 392.01476 | F22: =F13-F19 -> 417.04593 | G22: =G13-G19 -> 440.1437 | H22: =H13-H19 -> 461.05344 | I22: =I13-I19 -> 479.52718
B23: Ending Book Value | D23: =D21+D22 -> 2971.2159 | E23: =E21+E22 -> 3363.2307 | F23: =F21+F22 -> 3780.2766 | G23: =G21+G22 -> 4220.4203 | H23: =H21+H22 -> 4681.4737 | I23: =I21+I22 -> 5161.0009
B25: Valuation Date | D25: 45945
B26: Fiscal Year end date after Valuation Date | D26: 46112
B28: Year Frac | D28: =YEARFRAC($D$25,$D$26) -> 0.46111111 | E28: =D28+1 -> 1.4611111 | F28: =E28+1 -> 2.4611111 | G28: =F28+1 -> 3.4611111 | H28: =G28+1 -> 4.4611111 | I28: =H28+1 -> 5.4611111
B29: Discount Factor | D29: =1/(1+$I$8)^D28 -> 0.94235389 | E29: =1/(1+$I$8)^E28 -> 0.82850025 | F29: =1/(1+$I$8)^F28 -> 0.72840222 | G29: =1/(1+$I$8)^G28 -> 0.64039787 | H29: =1/(1+$I$8)^H28 -> 0.56302606 | I29: =1/(1+$I$8)^I28 -> 0.49500218
B31: PV of Excess Return | D31: =D$29*D15 -> 123.77224 | E31: =E$29*E15 -> 58.646651 | F31: =F$29*F15 -> 48.518892 | G31: =G$29*G15 -> 38.626884 | H31: =H$29*H15 -> 29.268922 | I31: =I$29*I15 -> 20.643717
B32: PV of Terminal Excess Return | I32: =I$29*I16 -> 10635.541
B34: Total PV of Excess Return | D34: =SUM(D31:I32) -> 10955.018
B35: Total Equity Value | D35: =D34+D21 -> 13516.458
B37: Shares Outstanding | D37: 7.14
B39: Implied Share Price | D39: =D35/D37 -> 1893.0614
C41: INR, bull | D41: =$D$39*(1+$D$44) -> 2082.3675
C42: INR, bear | D42: =$D$39*(1-$D$44) -> 1703.7553
C44: Range | D44: 0.1
C45: INR/USD, 15 Oct 25 | D45: =1/88.2898 -> 0.011326337
C46: INR, base | D46: =D39*$D$45 -> 21.441451
C48: USD, bull | D48: =D41*$D$45 -> 23.585596
C49: USD, bear | D49: =D42*$D$45 -> 19.297306

Sheet DDM
B2: ="Exihibit "&VLOOKUP(B3,TOC!$B$7:$D$13,3,FALSE) -> Exihibit 2
B3: Dividend Discount Model
B4: (In INR bn.)
B6: Assumptions
B7: Average Net Profit Margin (5yr) | C7: ='Residual Income'!C7 -> 0.25939811 | E7: Return on Equity | I7: ='Residual Income'!I7 -> 0.1747227
B8: Current DPR | C8: ='Residual Income'!C8 -> 0.1522 | E8: Cost of Equity | I8: ='Residual Income'!I8 -> 0.13742137
B9: Target DPR | C9: ='Residual Income'!C9 -> 0.3 | E9: Sustainable Growth Rate | I9: ='Residual Income'!I9 -> 0.1352179
B11: Fiscal Year ending March | D11: 2025 | E11: =D11+1 -> 2026 | F11: =E11+1 -> 2027 | G11: =F11+1 -> 2028 | H11: =G11+1 -> 2029 | I11: =H11+1 -> 2030
B13: Net Income | D13: =$C$7*Regression!O8 -> 483.34029 | E13: =$C$7*Regression!P8 -> 479.09508 | F13: =$C$7*Regression!Q8 -> 528.78979 | G13: =$C$7*Regression!R8 -> 579.8078 | H13: =$C$7*Regression!S8 -> 631.96096 | I13: =$C$7*Regression!T8 -> 685.03883
B15: Dividend Payout Ratio | D15: =C8 -> 0.1522 | E15: =D15+(($C$9-$D$15)/5) -> 0.18176 | F15: =E15+(($C$9-$D$15)/5) -> 0.21132 | G15: =F15+(($C$9-$D$15)/5) -> 0.24088 | H15: =G15+(($C$9-$D$15)/5) -> 0.27044 | I15: =H15+(($C$9-$D$15)/5) -> 0.3
B16: Dividends | D16: =D13*D15 -> 73.564392 | E16: =E13*E15 -> 87.080322 | F16: =F13*F15 -> 111.74386 | G16: =G13*G15 -> 139.6641 | H16: =H13*H15 -> 170.90752 | I16: =I13*I15 -> 205.51165
B17: Terminal Value of Dividends | I17: =I16*(1+I9)/(I8-I9) -> 105878.59
B19: Valuation Date | D19: 45945
B20: Fiscal Year end date after Valuation Date | D20: 46112
B22: Year Frac | D22: =YEARFRAC($D$19,$D$20,1) -> 0.45753425 | E22: =D22+1 -> 1.4575342 | F22: =E22+1 -> 2.4575342 | G22: =F22+1 -> 3.4575342 | H22: =G22+1 -> 4.4575342 | I22: =H22+1 -> 5.4575342
B23: Discount Factor | D23: =1/(1+$I$8)^D22 -> 0.94278801 | E23: =1/(1+$I$8)^E22 -> 0.82888192 | F23: =1/(1+$I$8)^F22 -> 0.72873778 | G23: =1/(1+$I$8)^G22 -> 0.64069288 | H23: =1/(1+$I$8)^H22 -> 0.56328543 | I23: =1/(1+$I$8)^I22 -> 0.49523021
B25: PV of Dividends | D25: =D16*D$23 -> 69.355627 | E25: =E16*E$23 -> 72.179305 | F25: =F16*F$23 -> 81.431972 | G25: =G16*G$23 -> 89.481797 | H25: =H16*H$23 -> 96.269717 | I25: =I16*I$23 -> 101.77558
I26: =I17*I$23 -> 52434.275
B28: Total PV of Dividends | D28: =SUM(D25:I26) -> 52944.769
B29: Shares O/S | D29: ='Residual Income'!D37 -> 7.14
B31: Implied Share Price | D31: =D28/D29 -> 7415.2338

Sheet Ratios
B2: ="Exihibit "&VLOOKUP(B3,TOC!$B$7:$D$13,3,FALSE) -> Exihibit 3
B3: Ratios
B6: Assumptions
B7: Average Net Profit Margin (5yr) | D7: ='Residual Income'!C7 -> 0.25939811 | F7: Return on Equity | H7: ='Residual Income'!I7 -> 0.1747227
B8: Current DPR | D8: ='Residual Income'!C8 -> 0.1522 | F8: Cost of Equity | H8: ='Residual Income'!I8 -> 0.13742137
B9: Target DPR | D9: ='Residual Income'!C9 -> 0.3 | F9: Sustainable Growth Rate | H9: 0.134
B10: BVPS | D10: =AVERAGE('Residual Income'!D21,'Residual Income'!D23)/'Residual Income'!D37 -> 387.44089
B12: Justified PE | D12: =D8*(1+H9)/(H8-H9) -> 50.4461
B14: Justified PB | D14: =(H7-H9)/(H8-H9) -> 11.902453
B16: Justified Dividend Yield | D16: =(H8-H9)/(1+H9) -> 0.0030170816
B18: P/B using ERM | D18: ='Residual Income'!D39/D10 -> 4.8860651
B19: P/B using DDM | D19: =DDM!D31/D10 -> 19.139007

Sheet WACC
B2: ="Exihibit "&VLOOKUP(B3,TOC!$B$7:$D$13,3,FALSE) -> Exihibit 5
B3: Weighted Average Cost of Capital
B4: (In INR bn.)
B7: Cost of Equity - Capital Asset Pricing Model | G7: Beta Selection Criteria | L7: Beta Calculation | U7: Date | V7: Sensex | W7: %Change | X7: ICICI | Y7: %Change | AA7: Using 5yr Daily Returns
B9: Risk Free Rate | C9: [1] | D9: 0.06514 | G9: Switch | H9: ICICI's Levered Beta | L9: Co. Name | M9: Market Cap | N9: Levered Beta | O9: Total Debt | P9: Total Equity | Q9: Debt-to-Equity | R9: Effective Tax | S9: Weights | U9: Oct 26 2015 | V9: 26656.83 | X9: 251.82 | AA9: raw beta | AB9: 1.18
B10: Beta | D10: =VLOOKUP(H9,$G$11:$J$12,4,TRUE) -> 1.12006 | L10: ICICI Bank | M10: 9932 | N10: =AB10 -> 1.12006 | O10: 18605 | P10: 3518 | Q10: =O10/P10 -> 5.2885162 | R10: =AVERAGE('[2]Income Statement'!E76:I76) -> 0.24649568 | S10: =M10/SUM($M$10:$M$22) -> 0.20863355 | U10: Nov 02 2015 | V10: 26265.24 | W10: =V10/V9-1 -> -0.014690044 | X10: 242.82 | Y10: =X10/X9-1 -> -0.035739814 | AA10: adjusted beta | AB10: =(AB9*0.667)+(1*0.333) -> 1.12006
B11: Expected Return from Equity Market | D11: =AB13 -> 0.12190604 | G11: ICICI's Levered Beta | J11: =N10 -> 1.12006 | U11: Nov 09 2015 | V11: 25610.53 | W11: =V11/V10-1 -> -0.024926862 | X11: 237.95 | Y11: =X11/X10-1 -> -0.020056009
B12: Equity Risk Premium | C12: [2] | D12: =D11-D9 -> 0.05676604 | G12: Peer's Median Levered Beta | J12: =M28 -> 1.7113582 | L12: Peers: | U12: Nov 16 2015 | V12: 25868.49 | W12: =V12/V11-1 -> 0.010072419 | X12: 240.86 | Y12: =X12/X11-1 -> 0.01222946 | AA12: 10yr CAGR
B13: Country Risk Premium | C13: [3] | D13: 0.0087 | L13: HDFC Bank | M13: 15409 | N13: 1.07 | O13: 33976 | P13: 5391 | Q13: =O13/P13 -> 6.3023558 | R13: 0.2361 | S13: =M13/SUM($M$10:$M$22) -> 0.32368449 | U13: Nov 23 2015 | V13: 26128.2 | W13: =V13/V12-1 -> 0.010039627 | X13: 245.5 | Y13: =X13/X12-1 -> 0.019264303 | AA13: Sensex | AB13: =_xlfn.RRI(10,V9,V530) -> 0.12190604
B14: Cost of Equity | D14: =D9+D10*D12+D13 -> 0.13742137 | G14: Share Price using ERM | J14: ='Residual Income'!D39 -> 1893.0614 | L14: State Bank of India | M14: 8374 | N14: 1.17 | O14: 61205 | P14: 4870 | Q14: =O14/P14 -> 12.567762 | R14: 0.2601 | S14: =M14/SUM($M$10:$M$22) -> 0.17590589 | U14: Nov 30 2015 | V14: 25638.11 | W14: =V14/V13-1 -> -0.018757128 | X14: 237.68 | Y14: =X14/X13-1 -> -0.03185336 | AA14: ICICI Bank | AB14: =_xlfn.RRI(10,X9,X530) -> 0.18524039
G15: Share Price using DDM | J15: =DDM!D31 -> 7415.2338 | L15: Axis Bank | M15: 3804 | N15: 1.09 | O15: 14424 | P15: 1983 | Q15: =O15/P15 -> 7.2738275 | R15: 0.2586 | S15: =M15/SUM($M$10:$M$22) -> 0.079907573 | U15: Dec 07 2015 | V15: 25044.43 | W15: =V15/V14-1 -> -0.023156153 | X15: 226.64 | Y15: =X15/X14-1 -> -0.046449007
B16: Cost of Debt | L16: Kotak Mahindra | M16: 4402 | N16: 1 | O16: 5923 | P16: 1575 | Q16: =O16/P16 -> 3.7606349 | R16: 0.2683 | S16: =M16/SUM($M$10:$M$22) -> 0.092469278 | U16: Dec 14 2015 | V16: 25519.22 | W16: =V16/V15-1 -> 0.018957908 | X16: 227.36 | Y16: =X16/X15-1 -> 0.0031768443
B17: Default Spread | C17: =A31 -> [4] | D17: 0.012 | L17: Punjab National Bank | M17: 1356 | N17: 1.19 | O17: 17382 | P17: 1422 | Q17: =O17/P17 -> 12.223629 | R17: 0.2572 | S17: =M17/SUM($M$10:$M$22) -> 0.028484403 | U17: Dec 21 2015 | V17: 25838.71 | W17: =V17/V16-1 -> 0.012519583 | X17: 234.5 | Y17: =X17/X16-1 -> 0.031403941
B18: Pre-Tax Cost of Debt | D18: =D17+D9 -> 0.07714 | L18: Canara Bank | M18: 1153 | N18: 1.3 | O18: 15461 | P18: 1097.5 | Q18: =O18/P18 -> 14.087472 | R18: 0.2471 | S18: =M18/SUM($M$10:$M$22) -> 0.024220145 | U18: Dec 28 2015 | V18: 26160.9 | W18: =V18/V17-1 -> 0.012469276 | X18: 239.09 | Y18: =X18/X17-1 -> 0.019573561
B19: Tax Rate | C19: =A32 -> [5] | D19: =R24 -> 0.26708143 | L19: Bank of Baroda | M19: 1397 | N19: 1.22 | O19: 15932 | P19: 1550 | Q19: =O19/P19 -> 10.27871 | R19: 0.368 | S19: =M19/SUM($M$10:$M$22) -> 0.029345657 | U19: Jan 04 2016 | V19: 24934.33 | W19: =V19/V18-1 -> -0.046885619 | X19: 222.77 | Y19: =X19/X18-1 -> -0.068258815
B20: Post-Tax Cost of Debt [Pre-Tax Ke*(1-Tax Rate)] | D20: =D18*(1-D19) -> 0.056537339 | L20: Bank of India | M20: 593 | N20: 1.11 | O20: 9748 | P20: 837 | Q20: =O20/P20 -> 11.646356 | R20: 0.342 | S20: =M20/SUM($M$10:$M$22) -> 0.012456675 | U20: Jan 11 2016 | V20: 24455.04 | W20: =V20/V19-1 -> -0.019222093 | X20: 204.05 | Y20: =X20/X19-1 -> -0.084032859
L21: The Federal Bank | M21: 559 | N21: 1.06 | O21: 3158 | P21: 354.53 | Q21: =O21/P21 -> 8.9075678 | R21: 0.254 | S21: =M21/SUM($M$10:$M$22) -> 0.011742464 | U21: Jan 18 2016 | V21: 24435.66 | W21: =V21/V20-1 -> -0.00079247468 | X21: 211.59 | Y21: =X21/X20-1 -> 0.036951728
B22: Weight of Equity | D22: =P24/(O24+P24) -> 0.10352631 | L22: IDFC First Bank | M22: 626 | N22: 1.13 | O22: 3175 | P22: 381.56 | Q22: =O22/P22 -> 8.3211028 | R22: 0.2 | S22: =M22/SUM($M$10:$M$22) -> 0.013149879 | U22: Jan 25 2016 | V22: 24870.69 | W22: =V22/V21-1 -> 0.01780308 | X22: 209.23 | Y22: =X22/X21-1 -> -0.011153646
B23: Weight of Debt | D23: =100%-D22 -> 0.89647369 | U23: Feb 01 2016 | V23: 24616.97 | W23: =V23/V22-1 -> -0.010201567 | X23: 190.36 | Y23: =X23/X22-1 -> -0.090187832
L24: Mean | N24: =AVERAGE(N$10:N$22) -> 1.1327327 | O24: =AVERAGE(O$10:O$22) -> 18089.909 | P24: =AVERAGE(P$10:P$22) -> 2089.0536 | Q24: =AVERAGE(Q$10:Q$22) -> 9.1507212 | R24: =AVERAGE(R$10:R$22) -> 0.26708143 | U24: Feb 08 2016 | V24: 22986.12 | W24: =V24/V23-1 -> -0.066249014 | X24: 175.95 | Y24: =X24/X23-1 -> -0.075698676
B25: WACC | D25: =(D14*D22)+(D20*D23) -> 0.064910965 | L25: Median | N25: =MEDIAN(N$10:N$22) -> 1.12006 | O25: =MEDIAN(O$10:O$22) -> 15461 | P25: =MEDIAN(P$10:P$22) -> 1550 | Q25: =MEDIAN(Q$10:Q$22) -> 8.9075678 | R25: =MEDIAN(R$10:R$22) -> 0.2572 | U25: Feb 15 2016 | V25: 23709.15 | W25: =V25/V24-1 -> 0.031455069 | X25: 180.73 | Y25: =X25/X24-1 -> 0.027166809
U26: Feb 22 2016 | V26: 23154.3 | W26: =V26/V25-1 -> -0.023402357 | X26: 168 | Y26: =X26/X25-1 -> -0.070436563
B27: Footnotes: | L27: Unlevered Beta | M27: =N10/(1+((1-R10)*Q10)) -> 0.22468967 | U27: Feb 29 2016 | V27: 24646.48 | W27: =V27/V26-1 -> 0.064445049 | X27: 200.45 | Y27: =X27/X26-1 -> 0.19315476
A28: [1] | B28: Source: 10 year Govermnet Bond Yield | L28: Re-levered Beta | M28: =M27*(1+(1-R25)*Q25) -> 1.7113582 | U28: Mar 07 2016 | V28: 24717.99 | W28: =V28/V27-1 -> 0.0029014285 | X28: 194.41 | Y28: =X28/X27-1 -> -0.030132203
A29: [2] | B29: Source: NSE, BSE, Yahoo Finance | U29: Mar 14 2016 | V29: 24952.74 | W29: =V29/V28-1 -> 0.0094971314 | X29: 209.27 | Y29: =X29/X28-1 -> 0.076436397
A30: [3] | B30: India's 5yr CDS spread | U30: Mar 21 2016 | V30: 25337.56 | W30: =V30/V29-1 -> 0.015421954 | X30: 212.91 | Y30: =X30/X29-1 -> 0.017393797
A31: [4] | B31: Synthetic Rating Method (Aswath Damodaran) | U31: Mar 28 2016 | V31: 25269.64 | W31: =V31/V30-1 -> -0.0026806054 | X31: 216.64 | Y31: =X31/X30-1 -> 0.01751914
A32: [5] | B32: Average Effective Tax Rate | U32: Apr 04 2016 | V32: 24673.84 | W32: =V32/V31-1 -> -0.0235777 | X32: 201.14 | Y32: =X32/X31-1 -> -0.071547267
U33: Apr 11 2016 | V33: 25626.75 | W33: =V33/V32-1 -> 0.038620255 | X33: 218.77 | Y33: =X33/X32-1 -> 0.087650393
U34: Apr 18 2016 | V34: 25838.14 | W34: =V34/V33-1 -> 0.0082488025 | X34: 229.09 | Y34: =X34/X33-1 -> 0.04717283
U35: Apr 25 2016 | V35: 25606.62 | W35: =V35/V34-1 -> -0.0089603973 | X35: 215.41 | Y35: =X35/X34-1 -> -0.059714523
U36: May 02 2016 | V36: 25228.5 | W36: =V36/V35-1 -> -0.014766494 | X36: 198.73 | Y36: =X36/X35-1 -> -0.077433731
U37: May 09 2016 | V37: 25489.57 | W37: =V37/V36-1 -> 0.010348217 | X37: 205.91 | Y37: =X37/X36-1 -> 0.036129422
U38: May 16 2016 | V38: 25301.9 | W38: =V38/V37-1 -> -0.0073626193 | X38: 200.09 | Y38: =X38/X37-1 -> -0.028264776
U39: May 23 2016 | V39: 26653.6 | W39: =V39/V38-1 -> 0.053422865 | X39: 221.05 | Y39: =X39/X38-1 -> 0.10475286
U40: May 30 2016 | V40: 26843.03 | W40: =V40/V39-1 -> 0.0071071075 | X40: 221.59 | Y40: =X40/X39-1 -> 0.0024428862
U41: Jun 06 2016 | V41: 26635.75 | W41: =V41/V40-1 -> -0.0077219301 | X41: 229.64 | Y41: =X41/X40-1 -> 0.036328354
U42: Jun 13 2016 | V42: 26625.91 | W42: =V42/V41-1 -> -0.00036942831 | X42: 216.77 | Y42: =X42/X41-1 -> -0.056044243
U43: Jun 20 2016 | V43: 26397.71 | W43: =V43/V42-1 -> -0.0085705991 | X43: 209.95 | Y43: =X43/X42-1 -> -0.031461918
U44: Jun 27 2016 | V44: 27144.91 | W44: =V44/V43-1 -> 0.028305486 | X44: 218.5 | Y44: =X44/X43-1 -> 0.040723982
...

Sheet Regression
B2: ="Exihibit "&VLOOKUP(B3,TOC!$B$7:$D$13,3,FALSE) -> Exihibit 7
B3: Regression Analysis
B4: (In INR bn.)
B6: Fiscal Year ending March | E6: 2015 | F6: =E6+1 -> 2016 | G6: =F6+1 -> 2017 | H6: =G6+1 -> 2018 | I6: =H6+1 -> 2019 | J6: =I6+1 -> 2020 | K6: =J6+1 -> 2021 | L6: =K6+1 -> 2022 | M6: =L6+1 -> 2023 | ... T6: =S6+1 -> 2030
B8: Revenue | E8: 549.64 | F8: 592.94 | G8: 609.4 | H8: 621.6 | I8: 719.8 | J8: 848.36 | K8: 891.62664 | L8: 954.06865 | M8: 1210.6681 | N8: 1595.1593 | O8: 1863.3146 | P8: =$H$32+($H$33*P10)+($H$34*P12) -> 1846.949 | Q8: =$H$32+($H$33*Q10)+($H$34*Q12) -> 2038.526 | R8: =$H$32+($H$33*R10)+($H$34*R12) -> 2235.2044 | S8: =$H$32+($H$33*S10)+($H$34*S12) -> 2436.259 | T8: =$H$32+($H$33*T10)+($H$34*T12) -> 2640.8783
B9: % Growth | F9: =F8/E8-1 -> 0.078778837 | G9: =G8/F8-1 -> 0.027759976 | H9: =H8/G8-1 -> 0.020019691 | I9: =I8/H8-1 -> 0.15797941 | J9: =J8/I8-1 -> 0.17860517 | K9: =K8/J8-1 -> 0.051000328 | L9: =L8/K8-1 -> 0.070031573 | M9: =M8/L8-1 -> 0.26895281 | ... T9: =T8/S8-1 -> 0.083989158
B10: India GDP (in trillion) | E10: 2.1 | F10: 2.29 | G10: 2.65 | H10: 2.7 | I10: 2.84 | J10: 2.67 | K10: 3.17 | L10: 3.35 | M10: 3.64 | N10: 3.91 | O10: 4.1981815 | P10: =O10*(1+P11) -> 4.4960968 | Q10: =P10*(1+Q11) -> 4.8028305 | R10: =Q10*(1+R11) -> 5.117327 | S10: =R10*(1+S11) -> 5.4383919 | T10: =S10*(1+T11) -> 5.7646954
B11: % Growth | F11: =F10/E10-1 -> 0.09047619 | G11: =G10/F10-1 -> 0.15720524 | H11: =H10/G10-1 -> 0.018867925 | I11: =I10/H10-1 -> 0.051851852 | J11: =J10/I10-1 -> -0.059859155 | K11: =K10/J10-1 -> 0.18726592 | L11: =L10/K10-1 -> 0.056782334 | M11: =M10/L10-1 -> 0.086567164 | ... O11: =O10/N10-1 -> 0.073703699 | P11: =O11-($O$11-$T$11)/5 -> 0.070962959 | Q11: =P11-($O$11-$T$11)/5 -> 0.068222219 | R11: =Q11-($O$11-$T$11)/5 -> 0.06548148 | S11: =R11-($O$11-$T$11)/5 -> 0.06274074 | T11: 0.06
B12: Lagged GDP | E12: 1.86 | F12: =E10 -> 2.1 | G12: =F10 -> 2.29 | H12: =G10 -> 2.65 | I12: =H10 -> 2.7 | J12: =I10 -> 2.84 | K12: =J10 -> 2.67 | L12: =K10 -> 3.17 | M12: =L10 -> 3.35 | ... T12: =S10 -> 5.4383919
B16: =B8 -> Revenue | C16: =B10 -> India GDP (in trillion) | D16: =B12 -> Lagged GDP | G16: SUMMARY OUTPUT
B17: {=TRANSPOSE(E8:O8)} -> 549.64 | C17: {=TRANSPOSE(E10:O10)} -> 2.1 | D17: {=TRANSPOSE(E12:O12)} -> 1.86
B18: 592.94 | C18: 2.29 | D18: 2.1 | G18: Regression Statistics
B19: 609.4 | C19: 2.65 | D19: 2.29 | G19: Multiple R | I19: 0.9453578
B20: 621.6 | C20: 2.7 | D20: 2.65 | G20: R Square | I20: 0.89370137
B21: 719.8 | C21: 2.84 | D21: 2.7 | G21: Adjusted R Square | I21: 0.86712672
B22: 848.36 | C22: 2.67 | D22: 2.84 | G22: Standard Error | I22: 158.7516
B23: 891.62664 | C23: 3.17 | D23: 2.67 | G23: Observations | I23: 11
B24: 954.06865 | C24: 3.35 | D24: 3.17
B25: 1210.6681 | C25: 3.64 | D25: 3.35 | G25: ANOVA
B26: 1595.1593 | C26: 3.91 | D26: 3.64 | H26: df | I26: SS | J26: MS | K26: F | L26: Significance F
B27: 1863.3146 | C27: 4.1981815 | D27: 3.91 | G27: Regression | H27: 2 | I27: 1695083.1 | J27: 847541.54 | K27: 33.629837 | L27: 0.0001276764
G28: Residual | H28: 8 | I28: 201616.57 | J28: 25202.071
G29: Total | H29: 10 | I29: 1896699.6
H31: Coefficients | I31: Standard Error | J31: t Stat | K31: P-value | L31: Lower 95% | M31: Upper 95% | N31: Lower 95.0% | O31: Upper 95.0%
G32: Intercept | H32: -927.81241 | I32: 234.15383 | J32: -3.9624054 | K32: 0.0041629786 | L32: -1467.7721 | M32: -387.8527 | N32: -1467.7721 | O32: -387.8527
G33: X Variable 1 | H33: 432.3981 | I33: 290.34729 | J33: 1.4892445 | K33: 0.17474966 | L33: -237.14396 | M33: 1101.9402 | N33: -237.14396 | O33: 1101.9402
G34: X Variable 2 | H34: 197.86131 | I34: 304.78839 | J34: 0.64917602 | K34: 0.53441391 | L34: -504.98198 | M34: 900.7046 | N34: -504.98198 | O34: 900.7046
